Workbook
Name MAINTABLE: [9]적정심사!$D$5:$AS$34
Name 단가내부코드: [9]단가!$D$15:$D$2646
Name 단가코드: [9]단가!$A$15:$A$2646

Sheet 산정기준(적정)
A1: 공사기간 산정 기준
A2: 공사명 : | B2: 하동군 보건의료원 건립공사 | D2: ▣ 가동율(광양지역 / 주6일) : Cal-1(토목) -68.8%, Cal-2(골조) - 62.7%, Cal-3(외부마감) - 64.9%, Cal-4(내부마감) - 68.8%, Cal-5(골조타설) - 52.6% | O2: 25. 07. 03
A3: 구분 | B3: 공정 | C3: 공종 | D3: 수량산출(개산) | E3: 단위 | F3: 내역수량 | G3: 생산성 | H3: 투입조 | I3: 생산량/일 | J3: 작업기간 (W.D) | K3: 가동율 | L3: Calender Day | N3: 비고 | O3: 표준품셈
A4: 적정공기 계획 | L4: =L85 -> 618.85908 | M4: =M85 -> 20.390101
A5: 1. 공사준비 | L5: 45 | M5: =L5/30 -> 1.5
A6: 공사준비 | B6: 설계도서 검토, 하도급업체의 선정 및 가설공사 | D6: 고시 제2021-1080호 제7조(준비기간 산정) 기준 | E6: 식 | L6: 45 | M6: =L6/30 -> 1.5
A7: 공통가설 | B7: 공통가설 | C7: 조립식가설사무소 | D7: 안전관리계획서, 착공계 | E7: M2 | F7: 558 | G7: 2.7 | H7: 1 | I7: =G7*H7 -> 2.7 | J7: =(F7/I7) -> 206.66667 | K7: 0.688 | L7: =J7/K7 -> 300.3876 | M7: =L7/30 -> 10.01292
C8: 조립식가설울타리/E.G.I철판 | D8: H=4.0, 18개월, 세륜기, 가설출입구, 가설방음벽 | E8: M | F8: 295 | G8: 28 | H8: 1 | I8: =G8*H8 -> 28 | J8: =(F8/I8) -> 10.535714 | K8: 0.688 | L8: =J8/K8 -> 15.313538 | M8: =L8/30 -> 0.51045127
A9: 2. 토공사 | L9: =L10+L15+L16+L17+L18+L19+L21+L22 -> 160.53376 | M9: =L9/30.4 -> 5.2807158
A10: 철거 | B10: 철거 | C10: 무근콘크리트깨기 | D10: T=30cm미만(양호) | E10: M3 | F10: 46 | G10: =5.9*8 -> 47.2 | H10: 1 | I10: =G10*H10 -> 47.2 | J10: =(F10/I10) -> 0.97457627 | K10: 0.688 | L10: 60 | M10: =L10/30.4 -> 1.9736842 | O10: 8-2-13 대형브레이커('14, '17, '25년 보완)
C11: 철근콘크리트깨기 | D11: T=30cm미만(양호) | E11: M3 | F11: 45 | G11: =3.3*8 -> 26.4 | H11: 1 | I11: =G11*H11 -> 26.4 | J11: =(F11/I11) -> 1.7045455 | K11: 0.688 | O11: 8-2-13 대형브레이커('14, '17, '25년 보완)
C12: 아스팔트포장깨기 | D12: T=30cm미만 | E12: M3 | F12: 145 | G12: =16*8 -> 128 | H12: 1 | I12: =G12*H12 -> 128 | J12: =(F12/I12) -> 1.1328125 | K12: 0.688 | O12: 8-2-13 대형브레이커('14, '17, '25년 보완)
C13: 기계터파기/보통토사 | D13: TypeⅠ(지반 및 현장조건이 일반적인 경우) | E13: M3 | F13: 603 | G13: 560 | H13: 1 | I13: =G13*H13 -> 560 | J13: =(F13/I13) -> 1.0767857 | K13: 0.688 | O13: 3-2-4 터파기(기계)
C14: 되메우기/토사(소형장비) | D14: Q(시간당 다짐토량)=1000*V*W*D*E*f/N | E14: M3 | F14: 431 | G14: 110 | H14: 1 | I14: =G14*H14 -> 110 | J14: =(F14/I14) -> 3.9181818 | K14: 0.688 | O14: 3-4-1 흙쌓기
A15: 토공 | B15: 흙막이가시설 | C15: 강널말뚝(쉬트파일) 항발(전동식) | D15: Type3, ℓ=16m이하, 100본 이상 | E15: 본 | F15: 524 | G15: =(((0.75+0.02*40)*16+3.75)*1)/1 -> 28.55 | H15: 1 | I15: =G15*H15 -> 28.55 | J15: =(F15/I15) -> 18.353765 | K15: 0.688 | L15: =J15/K15 -> 26.676984 | M15: =L15/30.4 -> 0.87753238 | O15: 8-2-24 진동파일 해머('96년 보완)
C16: H파일 천공 후 근입(굴착식) | D16: 500mm미만, ℓ=20m이하, 50본 미만 | E16: 본 | F16: 43 | G16: 21.564482 | H16: 1 | I16: =G16*H16 -> 21.564482 | J16: =(F16/I16) -> 1.9940196 | K16: 0.688 | L16: =J16/K16 -> 2.8982843 | M16: =L16/30.4 -> 0.0953383 | O16: 5-3-1 기성말뚝 기초
C17: 버팀보 설치(9~11M이하) | D17: H-300~500 | E17: 본 | F17: 235 | G17: 8.2474227 | H17: 2 | I17: =G17*H17 -> 16.494845 | J17: =(F17/I17) -> 14.246875 | K17: 0.688 | L17: =J17/K17 -> 20.707667 | M17: =L17/30.4 -> 0.68117326 | O17: 5-1-2 H-Beam 설치
B18: 터파기 | C18: 구조물터파기(토사) | D18: 직상차 | E18: M3 | F18: =7374*0.25 -> 1843.5 | G18: 560 | H18: 1 | I18: =G18*H18 -> 560 | J18: =(F18/I18) -> 3.2919643 | K18: 0.688 | L18: =J18/K18 -> 4.7848318 | M18: =L18/30.4 -> 0.15739578 | O18: 3-2-4 터파기(기계)
C19: 구조물터파기(토사) | D19: 크람쉘 | E19: M3 | F19: =7374*0.75 -> 5530.5 | G19: 288.47 | H19: 1 | I19: =G19*H19 -> 288.47 | J19: =(F19/I19) -> 19.171838 | K19: 0.688 | L19: =J19/K19 -> 27.866043 | M19: =L19/30.4 -> 0.91664615 | O19: 실적치, 복공판 없음
C20: 되메우기/토사(백호90%+인력10%) | D20: Q(시간당 다짐토량)=1000*V*W*D*E*f/N | E20: M3 | F20: 484 | G20: 110 | H20: 1 | I20: =G20*H20 -> 110 | J20: =(F20/I20) -> 4.4 | K20: 0.688 | L20: =J20/K20 -> 6.3953488 | M20: =L20/30.4 -> 0.21037332 | N20: 병행작업 | O20: 3-4-1 흙쌓기
B21: 지정공사 | C21: 콘크리트파일 | D21: 콘크리트파일, PHC , Φ500*10.0M | E21: 본 | F21: 147 | G21: =21.5644820295983 -> 21.564482 | H21: 1 | I21: =G21*H21 -> 21.564482 | J21: =(F21/I21) -> 6.8167647 | K21: 0.688 | L21: =J21/K21 -> 9.9080882 | M21: =L21/30.4 -> 0.32592396 | O21: 5-3-1 기성말뚝 기초
C22: 말뚝두부정리(콘크리트) | D22: Φ500 | E22: 본 | F22: 147 | G22: 9.2592593 | H22: 3 | I22: =G22*H22 -> 27.777778 | J22: =(F22/I22) -> 5.292 | K22: 0.688 | L22: =J22/K22 -> 7.6918605 | M22: =L22/30.4 -> 0.25302173 | O22: 5-3-4 말뚝두부정리(콘크리트)
A23: 3. 골조공사 | L23: =L24+L29+L34+L39+L44 -> 202.32532 | M23: =L23/30.4 -> 6.6554381
A24: RC공사 | B24: 기초공사 | C24: 버림콘크리트(25-18-80) | D24: 버림 60mm | E24: M3 | F24: =1210*0.06 -> 72.6 | G24: 189 | H24: 1 | I24: =G24*H24 -> 189 | J24: =(F24/I24) -> 0.38412698 | K24: 0.627 | L24: =((J24+J25+J26)/K24)+(J27/K27)+J28 -> 30.395049 | M24: =L24/30.4 -> 0.99983712 | O24: 6-1-4 콘크리트 펌프차 타설
C25: 철근 현장가공 및 조립 | E25: TON | F25: 31.101 | G25: 4 | H25: 2 | I25: =G25*H25 -> 8 | J25: =(F25/I25) -> 3.887625 | K25: 0.627 | O25: 6-2-3 현장조립
C26: 유로폼 | D26: 보통, 0-7m이하 | E26: M2 | F26: 611.98 | G26: 35 | H26: 2 | I26: =G26*H26 -> 70 | J26: =(F26/I26) -> 8.7425714 | K26: 0.627 | O26: 6-3-3 유로폼 설치 및 해체
C27: 콘크리트 펌프차 타설(철근) | D27: 슬럼프 15cm 이상 | E27: M3 | F27: 1319.93 | G27: 189 | H27: 2 | I27: =G27*H27 -> 378 | J27: =(F27/I27) -> 3.4918783 | K27: 0.526 | O27: 6-1-4 콘크리트 펌프차 타설
C28: 양생 | J28: 3
B29: 지하1층 | C29: 철근 현장가공 및 조립 | E29: TON | F29: 75.866 | G29: 4 | H29: 3 | I29: =G29*H29 -> 12 | J29: =(F29/I29) -> 6.3221667 | K29: 0.627 | L29: =((J29+J30+J31)/K29)+(J32/K32)+J33 -> 55.359849 | M29: =L29/30.4 -> 1.8210477 | O29: 6-2-3 현장조립
C30: 유로폼, 합판, 경사 등 | D30: 보통, 0-7m이하 | E30: M2 | F30: =2250.83+595.21 -> 2846.04 | G30: 35 | H30: 6 | I30: =G30*H30 -> 210 | J30: =(F30/I30) -> 13.552571 | K30: 0.627 | O30: 6-3-3 유로폼 설치 및 해체
C31: 데크플레이트 | D31: TG35-150 | E31: M2 | F31: 1083.31 | G31: 20 | H31: 5 | I31: =G31*H31 -> 100 | J31: =(F31/I31) -> 10.8331 | K31: 0.627 | O31: 1-3-3 데크플레이트 설치('08, '18, '23년 보완)
C32: 콘크리트 펌프차 타설(철근) | D32: 슬럼프 15cm 이상 | E32: M3 | F32: 883.584 | G32: 156 | H32: 2 | I32: =G32*H32 -> 312 | J32: =(F32/I32) -> 2.832 | K32: 0.526 | O32: 6-1-4 콘크리트 펌프차 타설
C33: 양생 | H33: 1 | J33: 1
B34: 지상1층 | C34: 철근 현장가공 및 조립 | E34: TON | F34: =44630.9/1000 -> 44.6309 | G34: 4 | H34: 3 | I34: =G34*H34 -> 12 | J34: =(F34/I34) -> 3.7192417 | K34: 0.627 | L34: =((J34+J35+J36)/K34)+(J37/K37)+J38 -> 41.609345 | M34: =L34/30.4 -> 1.3687285 | O34: 6-2-3 현장조립
C35: 유로폼, 합판, 경사 등 | D35: 보통, 0-7m이하 | E35: M2 | F35: 1860.89 | G35: 35 | H35: 5 | I35: =G35*H35 -> 175 | J35: =(F35/I35) -> 10.633657 | K35: 0.627 | O35: 6-3-3 유로폼 설치 및 해체
C36: 데크플레이트 | D36: 'TG35-150 | E36: M2 | F36: 911.55 | G36: 20 | H36: 5 | I36: =G36*H36 -> 100 | J36: =(F36/I36) -> 9.1155 | K36: 0.627 | O36: 1-3-3 데크플레이트 설치('08, '18, '23년 보완)
C37: 콘크리트 펌프차 타설(철근) | D37: 슬럼프 15cm 이상 | E37: M3 | F37: 521.824 | G37: 156 | H37: 2 | I37: =G37*H37 -> 312 | J37: =(F37/I37) -> 1.6725128 | K37: 0.526 | O37: 6-1-4 콘크리트 펌프차 타설
C38: 양생 | H38: 1 | J38: 1
B39: 지상2층 | C39: 철근 현장가공 및 조립 | E39: TON | F39: =40841.1/1000 -> 40.8411 | G39: 4 | H39: 3 | I39: =G39*H39 -> 12 | J39: =(F39/I39) -> 3.403425 | K39: 0.627 | L39: =((J39+J40+J41)/K39)+(J42/K42)+J43 -> 34.780051 | M39: =L39/30.4 -> 1.1440806 | O39: 6-2-3 현장조립
C40: 유로폼, 합판, 경사 등 | D40: 보통, 0-7m이하 | E40: M2 | F40: 1787.09 | G40: 35 | H40: 5 | I40: =G40*H40 -> 175 | J40: =(F40/I40) -> 10.211943 | K40: 0.627 | O40: 6-3-3 유로폼 설치 및 해체
...

Sheet 산정기준 (18개월)
A1: 공사기간 산정 기준
A2: 공사명 : | B2: 하동군 보건의료원 건립공사 | D2: ▣ 가동율(광양지역 / 주6일) : Cal-1(토목) -68.8%, Cal-2(골조) - 62.7%, Cal-3(외부마감) - 64.9%, Cal-4(내부마감) - 68.8%, Cal-5(골조타설) - 54.8% | O2: 25. 07. 03
A3: 구분 | B3: 공정 | C3: 공종 | D3: 수량산출(개산) | E3: 단위 | F3: 내역수량 | G3: 생산성 | H3: 투입조 | I3: 생산량/일 | J3: 작업기간 (W.D) | K3: 가동율 | L3: Calender Day | N3: 비고 | O3: 표준품셈
A4: 적정공기 계획 | L4: =L85 -> 549.32181 | M4: =M85 -> 18.069796
A5: 1. 공사준비 | L5: 45 | M5: =L5/30 -> 1.5 | R5: 45 | S5: 1.5
A6: 공사준비 | B6: 설계도서 검토, 하도급업체의 선정 및 가설공사 | D6: 고시 제2021-1080호 제7조(준비기간 산정) 기준 | E6: 식 | L6: 45 | M6: =L6/30 -> 1.5 | R6: 45 | S6: 1.5
A7: 공통가설 | B7: 공통가설 | C7: 조립식가설사무소 | D7: 안전관리계획서, 착공계 | E7: M2 | F7: 558 | G7: 2.7 | H7: 1 | I7: =G7*H7 -> 2.7 | J7: =(F7/I7) -> 206.66667 | K7: 0.682 | L7: =J7/K7 -> 303.0303 | M7: =L7/30 -> 10.10101 | Q7: 0.688 | R7: 300.3876 | S7: 10.01292
C8: 조립식가설울타리/E.G.I철판 | D8: H=4.0, 18개월, 세륜기, 가설출입구, 가설방음벽 | E8: M | F8: 295 | G8: 28 | H8: 1 | I8: =G8*H8 -> 28 | J8: =(F8/I8) -> 10.535714 | K8: 0.682 | L8: =J8/K8 -> 15.448261 | M8: =L8/30 -> 0.51494205 | Q8: 0.688 | R8: 15.313538 | S8: 0.51045127
A9: 2. 토공사 | L9: =L10+L15+L16+L17+L18+L19+L21+L22 -> 144.08262 | M9: =L9/30.4 -> 4.7395597 | R9: 143.34934 | S9: 4.7154387
A10: 철거 | B10: 철거 | C10: 무근콘크리트깨기 | D10: T=30cm미만(양호) | E10: M3 | F10: 46 | G10: =5.9*8 -> 47.2 | H10: 1 | I10: =G10*H10 -> 47.2 | J10: =(F10/I10) -> 0.97457627 | K10: 0.682 | L10: 60 | M10: =L10/30.4 -> 1.9736842 | O10: 8-2-13 대형브레이커('14, '17, '25년 보완) | P10: =L10*K10 -> 40.92 | Q10: 0.688 | R10: 60 | S10: 1.9736842
C11: 철근콘크리트깨기 | D11: T=30cm미만(양호) | E11: M3 | F11: 45 | G11: =3.3*8 -> 26.4 | H11: 1 | I11: =G11*H11 -> 26.4 | J11: =(F11/I11) -> 1.7045455 | K11: 0.682 | O11: 8-2-13 대형브레이커('14, '17, '25년 보완) | Q11: 0.688
C12: 아스팔트포장깨기 | D12: T=30cm미만 | E12: M3 | F12: 145 | G12: =16*8 -> 128 | H12: 1 | I12: =G12*H12 -> 128 | J12: =(F12/I12) -> 1.1328125 | K12: 0.682 | O12: 8-2-13 대형브레이커('14, '17, '25년 보완) | Q12: 0.688
C13: 기계터파기/보통토사 | D13: TypeⅠ(지반 및 현장조건이 일반적인 경우) | E13: M3 | F13: 603 | G13: 560 | H13: 1 | I13: =G13*H13 -> 560 | J13: =(F13/I13) -> 1.0767857 | K13: 0.682 | O13: 3-2-4 터파기(기계) | Q13: 0.688
C14: 되메우기/토사(소형장비) | D14: Q(시간당 다짐토량)=1000*V*W*D*E*f/N | E14: M3 | F14: 431 | G14: 110 | H14: 1 | I14: =G14*H14 -> 110 | J14: =(F14/I14) -> 3.9181818 | K14: 0.682 | O14: 3-4-1 흙쌓기 | Q14: 0.688
A15: 토공 | B15: 흙막이가시설 | C15: 강널말뚝(쉬트파일) 항발(전동식) | D15: Type3, ℓ=16m이하, 100본 이상 | E15: 본 | F15: 524 | G15: =(((0.75+0.02*40)*16+3.75)*1)/1 -> 28.55 | H15: 2 | I15: =G15*H15 -> 57.1 | J15: =(F15/I15) -> 9.1768827 | K15: 0.682 | L15: =J15/K15 -> 13.45584 | M15: =L15/30.4 -> 0.44262631 | O15: 8-2-24 진동파일 해머('96년 보완) | P15: =J15+J16+J17+J18+J19+J21+J22 -> 57.344344 | Q15: 0.688 | R15: 13.338492 | S15: 0.43876619
C16: 중앙파일 천공 후 근입(굴착식) | D16: 500mm미만, ℓ=20m이하, 50본 미만 | E16: 본 | F16: 43 | G16: 21.564482 | H16: 1 | I16: =G16*H16 -> 21.564482 | J16: =(F16/I16) -> 1.9940196 | K16: 0.682 | L16: =J16/K16 -> 2.9237824 | M16: =L16/30.4 -> 0.096177053 | O16: 5-3-1 기성말뚝 기초 | Q16: 0.688 | R16: 2.8982843 | S16: 0.0953383
C17: 버팀보 설치(9~11M이하) | D17: H-300~500 | E17: 본 | F17: 235 | G17: 8.2474227 | H17: 2 | I17: =G17*H17 -> 16.494845 | J17: =(F17/I17) -> 14.246875 | K17: 0.682 | L17: =J17/K17 -> 20.889846 | M17: =L17/30.4 -> 0.68716599 | O17: 5-1-2 H-Beam 설치 | Q17: 0.688 | R17: 20.707667 | S17: 0.68117326
B18: 터파기 | C18: 구조물터파기(토사) | D18: 직상차 | E18: M3 | F18: =7374*0.25 -> 1843.5 | G18: 560 | H18: 1 | I18: =G18*H18 -> 560 | J18: =(F18/I18) -> 3.2919643 | K18: 0.682 | L18: =J18/K18 -> 4.8269271 | M18: =L18/30.4 -> 0.1587805 | O18: 3-2-4 터파기(기계) | Q18: 0.688 | R18: 4.7848318 | S18: 0.15739578
C19: 구조물터파기(토사) | D19: 크람쉘 | E19: M3 | F19: =7374*0.75 -> 5530.5 | G19: 288.47 | H19: 1 | I19: =G19*H19 -> 288.47 | J19: =(F19/I19) -> 19.171838 | K19: 0.682 | L19: =J19/K19 -> 28.111199 | M19: =L19/30.4 -> 0.92471049 | O19: 실적치, 복공판 없음 | Q19: 0.688 | R19: 27.866043 | S19: 0.91664615
C20: 되메우기/토사(백호90%+인력10%) | D20: Q(시간당 다짐토량)=1000*V*W*D*E*f/N | E20: M3 | F20: 484 | G20: 110 | H20: 1 | I20: =G20*H20 -> 110 | J20: =(F20/I20) -> 4.4 | K20: 0.682 | L20: =J20/K20 -> 6.4516129 | M20: =L20/30.4 -> 0.21222411 | N20: 병행작업 | O20: 3-4-1 흙쌓기 | Q20: 0.688 | R20: 6.3953488 | S20: 0.21037332
B21: 지정공사 | C21: 콘크리트파일 | D21: 콘크리트파일, PHC , Φ500*10.0M | E21: 본 | F21: 147 | G21: =21.5644820295983 -> 21.564482 | H21: 1 | I21: =G21*H21 -> 21.564482 | J21: =(F21/I21) -> 6.8167647 | K21: 0.682 | L21: =J21/K21 -> 9.9952562 | M21: =L21/30.4 -> 0.32879132 | O21: 5-3-1 기성말뚝 기초 | Q21: 0.688 | R21: 9.9080882 | S21: 0.32592396
C22: 말뚝두부정리(콘크리트) | D22: Φ500 | E22: 본 | F22: 147 | G22: 9.2592593 | H22: 6 | I22: =G22*H22 -> 55.555556 | J22: =(F22/I22) -> 2.646 | K22: 0.682 | L22: =J22/K22 -> 3.8797654 | M22: =L22/30.4 -> 0.12762386 | O22: 5-3-4 말뚝두부정리(콘크리트) | Q22: 0.688 | R22: 3.8459302 | S22: 0.12651086
A23: 3. 골조공사 | L23: =L24+L29+L34+L39+L44 -> 148.23919 | M23: =L23/30.4 -> 4.8762892 | R23: 147.85145 | S23: 4.8635345
A24: RC공사 | B24: 기초공사 | C24: 버림콘크리트(25-18-80) | D24: 버림 60mm | E24: M3 | F24: =1210*0.06 -> 72.6 | G24: 189 | H24: 1 | I24: =G24*H24 -> 189 | J24: =(F24/I24) -> 0.38412698 | K24: 0.625 | L24: =((J24+J25+J26)/K24)+(J27/K27)+J28 -> 15.971752 | M24: =L24/30.4 -> 0.52538659 | O24: 6-1-4 콘크리트 펌프차 타설 | P24: =J24+J25+J26+J27+J28 -> 10.616698 | Q24: 0.627 | R24: 15.950701 | S24: 0.5246941
C25: 철근 현장가공 및 조립 | E25: TON | F25: 31.101 | G25: 4 | H25: 5 | I25: =G25*H25 -> 20 | J25: =(F25/I25) -> 1.55505 | K25: 0.625 | O25: 6-2-3 현장조립 | Q25: 0.627
C26: 유로폼 | D26: 보통, 0-7m이하 | E26: M2 | F26: 611.98 | G26: 35 | H26: 8 | I26: =G26*H26 -> 280 | J26: =(F26/I26) -> 2.1856429 | K26: 0.625 | O26: 6-3-3 유로폼 설치 및 해체 | Q26: 0.627
C27: 콘크리트 펌프차 타설(철근) | D27: 슬럼프 15cm 이상 | E27: M3 | F27: 1319.93 | G27: 189 | H27: 2 | I27: =G27*H27 -> 378 | J27: =(F27/I27) -> 3.4918783 | K27: 0.548 | O27: 6-1-4 콘크리트 펌프차 타설 | Q27: 0.548
C28: 양생 | J28: 3
B29: 지하1층 | C29: 철근 현장가공 및 조립 | E29: TON | F29: 75.866 | G29: 4 | H29: 5 | I29: =G29*H29 -> 20 | J29: =(F29/I29) -> 3.7933 | K29: 0.625 | L29: =((J29+J30+J31)/K29)+(J32/K32)+J33 -> 39.691765 | M29: =L29/30.4 -> 1.3056502 | O29: 6-2-3 현장조립 | P29: =J29+J30+J31+J32+J33 -> 24.784426 | Q29: 0.627 | R29: 39.584831 | S29: 1.3021326
C30: 유로폼, 합판, 경사 등 | D30: 보통, 0-7m이하 | E30: M2 | F30: =2250.83+595.21 -> 2846.04 | G30: 35 | H30: 10 | I30: =G30*H30 -> 350 | J30: =(F30/I30) -> 8.1315429 | K30: 0.625 | O30: 6-3-3 유로폼 설치 및 해체 | Q30: 0.627
C31: 데크플레이트 | D31: TG35-150 | E31: M2 | F31: 1083.31 | G31: 20 | H31: 6 | I31: =G31*H31 -> 120 | J31: =(F31/I31) -> 9.0275833 | K31: 0.625 | O31: 1-3-3 데크플레이트 설치('08, '18, '23년 보완) | Q31: 0.627
C32: 콘크리트 펌프차 타설(철근) | D32: 슬럼프 15cm 이상 | E32: M3 | F32: 883.584 | G32: 156 | H32: 2 | I32: =G32*H32 -> 312 | J32: =(F32/I32) -> 2.832 | K32: 0.548 | O32: 6-1-4 콘크리트 펌프차 타설 | Q32: 0.548
C33: 양생 | J33: 1
B34: 지상1층 | C34: 철근 현장가공 및 조립 | E34: TON | F34: =44630.9/1000 -> 44.6309 | G34: 4 | H34: 5 | I34: =G34*H34 -> 20 | J34: =(F34/I34) -> 2.231545 | K34: 0.625 | L34: =((J34+J35+J36)/K34)+(J37/K37)+J38 -> 30.41016 | M34: =L34/30.4 -> 1.0003342 | O34: 6-2-3 현장조립 | P34: =J34+J35+J36+J37+J38 -> 19.146344 | Q34: 0.627 | R34: 30.326083 | S34: 0.99756852
C35: 유로폼, 합판, 경사 등 | D35: 보통, 0-7m이하 | E35: M2 | F35: 1860.89 | G35: 35 | H35: 8 | I35: =G35*H35 -> 280 | J35: =(F35/I35) -> 6.6460357 | K35: 0.625 | O35: 6-3-3 유로폼 설치 및 해체 | Q35: 0.627
C36: 데크플레이트 | D36: 'TG35-150 | E36: M2 | F36: 911.55 | G36: 20 | H36: 6 | I36: =G36*H36 -> 120 | J36: =(F36/I36) -> 7.59625 | K36: 0.625 | O36: 1-3-3 데크플레이트 설치('08, '18, '23년 보완) | Q36: 0.627
C37: 콘크리트 펌프차 타설(철근) | D37: 슬럼프 15cm 이상 | E37: M3 | F37: 521.824 | G37: 156 | H37: 2 | I37: =G37*H37 -> 312 | J37: =(F37/I37) -> 1.6725128 | K37: 0.548 | O37: 6-1-4 콘크리트 펌프차 타설 | Q37: 0.548
C38: 양생 | J38: 1
B39: 지상2층 | C39: 철근 현장가공 및 조립 | E39: TON | F39: =40841.1/1000 -> 40.8411 | G39: 4 | H39: 5 | I39: =G39*H39 -> 20 | J39: =(F39/I39) -> 2.042055 | K39: 0.625 | L39: =((J39+J40+J41)/K39)+(J42/K42)+J43 -> 32.666197 | M39: =L39/30.4 -> 1.074546 | O39: 6-2-3 현장조립 | P39: =J39+J40+J41+J42+J43 -> 20.585298 | Q39: 0.627 | R39: 32.573725 | S39: 1.0715041
C40: 유로폼, 합판, 경사 등 | D40: 보통, 0-7m이하 | E40: M2 | F40: 1787.09 | G40: 35 | H40: 8 | I40: =G40*H40 -> 280 | J40: =(F40/I40) -> 6.3824643 | K40: 0.625 | O40: 6-3-3 유로폼 설치 및 해체 | Q40: 0.627
...

Sheet 공사예정공정표
A1: 공 사 예 정 공 정 표 | F1: 2025년 | L1: 2026년 | AV1: 2027년 | BN1: 비고
A2: 공사명 : | B2: 하동군 보건의료원 건립공사 | F2: 11 | I2: 12 | L2: 1 | O2: 2 | R2: 3 | U2: 4 | X2: 5 | AA2: 6 | AD2: 7 | AG2: 8 | AJ2: 9 | AM2: 10 | AP2: 11 | AS2: 12 | AV2: 1 | AY2: 2 | BB2: 3 | BE2: 4 | BH2: 5 | BK2: 6
A3: 구분 | B3: 공정 | C3: 공종 | D3: Calender Day | F3: =G3-10 -> -20 | G3: =H3-10 -> -10 | H3: =I3-10 -> 0 | I3: 10 | J3: =I3+10 -> 20 | K3: =J3+11 -> 31 | L3: =K3+10 -> 41 | M3: =L3+10 -> 51 | N3: =M3+11 -> 62 | O3: =N3+10 -> 72 | P3: =O3+10 -> 82 | Q3: =P3+8 -> 90 | R3: =Q3+10 -> 100 | S3: =R3+10 -> 110 | T3: =S3+11 -> 121 | U3: =T3+10 -> 131 | V3: =U3+10 -> 141 | W3: =V3+10 -> 151 | X3: =W3+10 -> 161 | Y3: =X3+10 -> 171 | Z3: =Y3+11 -> 182 | AA3: =Z3+10 -> 192 | AB3: =AA3+10 -> 202 | AC3: =AB3+10 -> 212 | AD3: =AC3+10 -> 222 | AE3: =AD3+10 -> 232 | AF3: =AE3+11 -> 243 | AG3: =AF3+10 -> 253 | AH3: =AG3+10 -> 263 | AI3: =AH3+11 -> 274 | AJ3: =AI3+10 -> 284 | AK3: =AJ3+10 -> 294 | AL3: =AK3+10 -> 304 | AM3: =AL3+10 -> 314 | AN3: =AM3+10 -> 324 | AO3: =AN3+11 -> 335 | AP3: =AO3+10 -> 345 | AQ3: =AP3+10 -> 355 | AR3: =AQ3+10 -> 365 | AS3: =AR3+10 -> 375 | AT3: =AS3+10 -> 385 | AU3: =AT3+11 -> 396 | AV3: =AU3+10 -> 406 | AW3: =AV3+10 -> 416 | AX3: =AW3+11 -> 427 | AY3: =AX3+10 -> 437 | AZ3: =AY3+10 -> 447 | BA3: =AZ3+8 -> 455 | BB3: =BA3+10 -> 465 | BC3: =BB3+10 -> 475 | BD3: =BC3+11 -> 486 | BE3: =BD3+10 -> 496 | BF3: =BE3+10 -> 506 | BG3: =BF3+10 -> 516 | BH3: =BG3+10 -> 526 | BI3: =BH3+10 -> 536 | BJ3: =BI3+11 -> 547 | BK3: =BJ3+10 -> 557 | BL3: =BK3+10 -> 567 | BM3: =BL3+10 -> 577
A4: 적정공기 계획 | D4: 중간관리일
A5: 1. 공사준비 | B5: 설계도서 검토, 하도급업체의 선정 및 가설공사 | D5: 45 | E5: =D5/30.4 -> 1.4802632
A6: 공통가설 | B6: 공통가설 | C6: 현장사무실, 안전관리계획서 | D6: 289.04429 | E6: =D6/30.4 -> 9.5080358
C7: 조립식가설울타리/E.G.I철판 | D7: 14.735265 | E7: =D7/30.4 -> 0.48471266
A8: 2. 토공사 | D8: ='산정기준 (18개월)'!L9 -> 144.08262 | E8: =D8/30.4 -> 4.7395597
A9: 철거 | B9: 철거 | C9: 기존 구조물 철거 | D9: ='산정기준 (18개월)'!L10 -> 60 | E9: =D9/30.4 -> 1.9736842
C10: 기계터파기/보통토사
C11: 되메우기/토사(소형장비)
A12: 토공 | B12: 흙막이가시설 | C12: 강널말뚝(쉬트파일) 항발(전동식) | D12: ='산정기준 (18개월)'!L15 -> 13.45584 | E12: =D12/30.4 -> 0.44262631
C13: H파일 천공 후 근입(굴착식) | D13: ='산정기준 (18개월)'!L16 -> 2.9237824 | E13: =D13/30.4 -> 0.096177053
C14: 버팀보 설치(9~11M이하) | D14: ='산정기준 (18개월)'!L17 -> 20.889846 | E14: =D14/30.4 -> 0.68716599
B15: 터파기 | C15: 구조물터파기(직상차) | D15: ='산정기준 (18개월)'!L18 -> 4.8269271 | E15: =D15/30.4 -> 0.1587805
C16: 구조물터파기(크람쉘) | D16: ='산정기준 (18개월)'!L19 -> 28.111199 | E16: =D16/30.4 -> 0.92471049
C17: 되메우기/토사(백호90%+인력10%) | D17: ='산정기준 (18개월)'!L20 -> 6.4516129 | E17: 병행
B18: 지정공사 | C18: 콘크리트파일 | D18: ='산정기준 (18개월)'!L21 -> 9.9952562 | E18: =D18/30.4 -> 0.32879132
C19: 말뚝두부정리(콘크리트) | D19: ='산정기준 (18개월)'!L22 -> 3.8797654 | E19: =D19/30.4 -> 0.12762386
A20: 3. 골조공사 | D20: ='산정기준 (18개월)'!L23 -> 148.23919 | E20: =D20/30.4 -> 4.8762892
A21: RC공사 | B21: 기초공사 | C21: 철근, 거푸집, 콘크리트 타설 | D21: ='산정기준 (18개월)'!L24 -> 15.971752 | E21: =D21/30.4 -> 0.52538659
D22: 148.67463 | E22: =D22/30.4 -> 4.8906129
D23: 16.217212 | E23: =D23/30.4 -> 0.53346092
E24: =D24/30.4 -> 0
E25: =D25/30.4 -> 0
B26: 지하1층 | C26: 철근, 거푸집, 콘크리트 타설 | D26: ='산정기준 (18개월)'!L29 -> 39.691765 | E26: =D26/30.4 -> 1.3056502
C27: 철근, 거푸집, 콘크리트 타설 | E27: =D27/30.4 -> 0
C28: 철근, 거푸집, 콘크리트 타설 | D28: 39.800978 | E28: =D28/30.4 -> 1.3092427
C29: 철근, 거푸집, 콘크리트 타설 | E29: =D29/30.4 -> 0
C30: 철근, 거푸집, 콘크리트 타설 | E30: =D30/30.4 -> 0
B31: 지상1층 | C31: 철근, 거푸집, 콘크리트 타설 | D31: ='산정기준 (18개월)'!L34 -> 30.41016 | E31: =D31/30.4 -> 1.0003342
C32: 철근, 거푸집, 콘크리트 타설 | E32: =D32/30.4 -> 0
C33: 철근, 거푸집, 콘크리트 타설 | D33: 30.453734 | E33: =D33/30.4 -> 1.0017676
C34: 철근, 거푸집, 콘크리트 타설 | E34: =D34/30.4 -> 0
C35: 철근, 거푸집, 콘크리트 타설 | E35: =D35/30.4 -> 0
B36: 지상2층 | C36: 철근, 거푸집, 콘크리트 타설 | D36: ='산정기준 (18개월)'!L39 -> 32.666197 | E36: =D36/30.4 -> 1.074546
C37: 철근, 거푸집, 콘크리트 타설 | E37: =D37/30.4 -> 0
C38: 철근, 거푸집, 콘크리트 타설 | D38: 32.685662 | E38: =D38/30.4 -> 1.0751862
C39: 철근, 거푸집, 콘크리트 타설 | E39: =D39/30.4 -> 0
C40: 철근, 거푸집, 콘크리트 타설 | E40: =D40/30.4 -> 0
...

Sheet 층별총집계표
A1: 층별 총집계표
A2: 공사명 : 과천 갈현초등학교 증축공사
A3: 층 | B3: 25-27-15 | C3: 25-30-15 | G3: 소계 | O3: D10 | P3: D13 | Q3: D16 | R3: D19 | S3: D22 | T3: D25 | U3: 소계 (KG)
B4: 유로폼복잡 | C4: 유로폼보통 | D4: 유로폼간단 | E4: 합판 2회 | G4: 소계 | O4: H10 | P4: H13 | Q4: H16 | R4: H19 | S4: H22 | T4: H25
A5: 동 명 : [ 신축동 ]
A6: FT | B6: 825.634 | C6: 3.3 | G6: =SUM(B6:F6) -> 828.934 | O6: =SUM(G6) -> 828.934 | P6: =SUM(H6) -> 0 | Q6: =SUM(I6) -> 0 | R6: =SUM(J6) -> 0 | S6: =SUM(K6) -> 0 | T6: =SUM(L6) -> 0 | U6: =SUM(M6) -> 0
B7: 1.16 | C7: 1.2 | D7: 917.36 | E7: 1.14 | G7: =SUM(B7:F7) -> 920.86 | O7: 833.6 | P7: 1676.3 | Q7: 39.8 | R7: 6601.7 | S7: 32728 | U7: =SUM(O7:T7) -> 41879.4
A8: B1 | B8: 225.392 | C8: 392.462 | G8: =SUM(B8:F8) -> 617.854 | U8: =SUM(M8) -> 0
B9: 57.28 | C9: 326.41 | D9: 62.17 | E9: 90.05 | G9: =SUM(B9:F9) -> 535.91 | O9: 17033.7 | P9: 6642.1 | Q9: 1691.8 | R9: 18762.5 | S9: 32633.8 | U9: =SUM(O9:T9) -> 76763.9
A10: 1 | C10: 566.73 | G10: =SUM(B10:F10) -> 566.73 | U10: =SUM(M10) -> 0
B11: 254.2 | C11: 2163.84 | E11: 63.87 | G11: =SUM(B11:F11) -> 2481.91 | O11: 34006.1 | P11: 9950.7 | Q11: 4207.7 | R11: 6948.6 | S11: 40174.8 | U11: =SUM(O11:T11) -> 95287.9
A12: 2 | B12: 0.225 | C12: 416.377 | G12: =SUM(B12:F12) -> 416.602 | U12: =SUM(M12) -> 0
B13: 155.52 | C13: 1309.38 | E13: 72.3 | G13: =SUM(B13:F13) -> 1537.2 | O13: 26247.8 | P13: 5844.6 | Q13: 6721.7 | R13: 4073.1 | S13: 33941 | U13: =SUM(O13:T13) -> 76828.2
A14: 3 | C14: 407.634 | G14: =SUM(B14:F14) -> 407.634 | U14: =SUM(M14) -> 0
B15: 154.84 | C15: 1225.5 | E15: 63.87 | G15: =SUM(B15:F15) -> 1444.21 | O15: 24962.3 | P15: 5426.5 | Q15: 6537 | R15: 3543.1 | S15: 34032.2 | U15: =SUM(O15:T15) -> 74501.1
A16: 4 | C16: 409.069 | G16: =SUM(B16:F16) -> 409.069 | U16: =SUM(M16) -> 0
B17: 154.84 | C17: 1238.46 | E17: 63.87 | G17: =SUM(B17:F17) -> 1457.17 | O17: 25029.8 | P17: 5426.5 | Q17: 6553.9 | R17: 3703.7 | S17: 34081.7 | U17: =SUM(O17:T17) -> 74795.6
A18: 5 | C18: 460.017 | G18: =SUM(B18:F18) -> 460.017 | U18: =SUM(M18) -> 0
B19: 163.72 | C19: 1734.91 | E19: 94.8 | G19: =SUM(B19:F19) -> 1993.43 | O19: 26243.3 | P19: 6640.6 | Q19: 6374.3 | R19: 7260.5 | S19: 32524.3 | U19: =SUM(O19:T19) -> 79043
A20: PH1 | C20: 76.893 | G20: =SUM(B20:F20) -> 76.893 | U20: =SUM(M20) -> 0
B21: 1.16 | C21: 471.28 | E21: 41.25 | G21: =SUM(B21:F21) -> 513.69 | O21: 4914.9 | P21: 3118.2 | Q21: 39.8 | R21: 62.3 | S21: 292.1 | U21: =SUM(O21:T21) -> 8427.3
A22: 계 | B22: =SUM(B6+B8+B10+B12+B14+B16+B18+B20) -> 1051.251 | C22: =SUM(C6+C8+C10+C12+C14+C16+C18+C20) -> 2732.482 | D22: =SUM(D6+D8+D10+D12+D14+D16+D18+D20) -> 0 | E22: =SUM(E6+E8+E10+E12+E14+E16+E18+E20) -> 0 | G22: =SUM(G6+G8+G10+G12+G14+G16+G18+G20) -> 3783.733 | H22: =SUM(H6+H8+H10+H12+H14+H16+H18+H20) -> 0 | I22: =SUM(I6+I8+I10+I12+I14+I16+I18+I20) -> 0 | J22: =SUM(J6+J8+J10+J12+J14+J16+J18+J20) -> 0 | K22: =SUM(K6+K8+K10+K12+K14+K16+K18+K20) -> 0 | L22: =SUM(L6+L8+L10+L12+L14+L16+L18+L20) -> 0 | M22: =SUM(M6+M8+M10+M12+M14+M16+M18+M20) -> 0 | N22: =SUM(N6+N8+N10+N12+N14+N16+N18+N20) -> 0 | ... U22: =SUM(U6+U8+U10+U12+U14+U16+U18+U20) -> 0
B23: =SUM(B7+B9+B11+B13+B15+B17+B19+B21) -> 942.72 | C23: =SUM(C7+C9+C11+C13+C15+C17+C19+C21) -> 8470.98 | D23: =SUM(D7+D9+D11+D13+D15+D17+D19+D21) -> 979.53 | E23: =SUM(E7+E9+E11+E13+E15+E17+E19+E21) -> 491.15 | G23: =SUM(G7+G9+G11+G13+G15+G17+G19+G21) -> 10884.38 | H23: =SUM(H7+H9+H11+H13+H15+H17+H19+H21) -> 0 | I23: =SUM(I7+I9+I11+I13+I15+I17+I19+I21) -> 0 | J23: =SUM(J7+J9+J11+J13+J15+J17+J19+J21) -> 0 | K23: =SUM(K7+K9+K11+K13+K15+K17+K19+K21) -> 0 | L23: =SUM(L7+L9+L11+L13+L15+L17+L19+L21) -> 0 | M23: =SUM(M7+M9+M11+M13+M15+M17+M19+M21) -> 0 | N23: =SUM(N7+N9+N11+N13+N15+N17+N19+N21) -> 0 | ... U23: =SUM(U7+U9+U11+U13+U15+U17+U19+U21) -> 527526.4

Sheet 토공기간 검토
A1: [공기 산출근거] 토공
A2: 공사명 : 과천 갈현초등학교 증축공사
A3: [ 기본조건 ] | K3: 2025. 07. 01
A4: * 직상차 | C4: * 반출 : 덤프트럭(25ton), 12m3(평적) 기준 | G4: * 세륜기 1대 운용 (통과시간 1.5분)
A5: * 주간 8hr, 적용(08:00~17:00, 점심 휴무) | C5: * 1조 : 흙깍기(백호, 0.7W) + 집토(도저) + 상차(백호, 0.7W) 운용
A7: 공 종 명 | B7: 규 격 | C7: 단위 | D7: 토 공 량 | E7: 산 출 조 건 | G7: 공사기간 산정 | K7: 비 고
D8: ① 수량 | E8: 일 작업량(Q) | F8: 일 반출량(M3) | G8: 작업일수 Working Day | H8: 가동율(%) : 토공사 | I8: 반출 일수 Calendar Day | J8: 소요개월
A9: 토사 | C9: M3 | D9: =D10+#REF!+D11 -> #REF! | F9: =E9*6 -> 0 | G9: =G10+#REF!+G11 -> #DIV/0! | H9: 0.729 | I9: =I10+#REF!+I11 -> #DIV/0! | J9: =I9/30 -> #DIV/0!
A10: 토사 흙깎기 | B10: 직상차 | C10: M3 | F10: =E10*1 -> 0 | G10: =D10/F10 -> #DIV/0! | H10: =H9 -> 0.729 | I10: =G10/H10 -> #DIV/0! | J10: =I10/30 -> #DIV/0! | K10: 백호(0.7W)
A11: 리핑암 흙깎기 | B11: 리핑암 | C11: M3 | F11: =E11*2 -> 0 | G11: =D11/F11 -> #DIV/0! | H11: =H9 -> 0.729 | I11: =G11/H11 -> #DIV/0! | J11: =I11/30 -> #DIV/0!
A12: 발파암 | C12: M3 | D12: =D13+D14+D15+D16 -> 0 | F12: =E12*4 -> 0 | G12: =G14 -> #DIV/0! | H12: =H9 -> 0.729 | I12: =G12/H12 -> #DIV/0! | J12: =I12/30 -> #DIV/0! | K12: 암발파 00조 적용
A13: 무진동 기계 암굴착 | B13: 천공기1대 | C13: M3 | F13: =E13*1 -> 0 | G13: =D13/F13 -> #DIV/0! | H13: =H9 -> 0.729 | I13: =G13/H13 -> #DIV/0! | J13: =I13/30 -> #DIV/0!
A14: 정밀진동제어발파 | B14: 천공기1대 | C14: M3 | F14: =E14*1 -> 0 | G14: =D14/F14 -> #DIV/0! | H14: =H9 -> 0.729 | I14: =G14/H14 -> #DIV/0! | J14: =I14/30 -> #DIV/0!
A15: 소규모 진동제어발파 | B15: 천공기1대 | C15: M3 | F15: =E15*1 -> 0 | G15: =D15/F15 -> #DIV/0! | H15: =H9 -> 0.729 | I15: =G15/H15 -> #DIV/0! | J15: =I15/30 -> #DIV/0!
A16: 중규모 진동제어발파 | B16: 천공기1대 | C16: M3 | F16: =E16*1 -> 0 | G16: =D16/F16 -> #DIV/0! | H16: =H9 -> 0.729 | I16: =G16/H16 -> #DIV/0! | J16: =I16/30 -> #DIV/0!
A17: 합 계 | D17: =D12+D9 -> #REF! | F17: =F12+F9 -> 0 | G17: =G12+G9 -> #DIV/0! | H17: =H9 -> 0.729 | I17: =I12+I9 -> #DIV/0! | J17: =J9+J12 -> #DIV/0!
A18: ■ 세륜기 반영 작업량 _ 1.5분/대 적용 시 : (60min / 1.5min) * 8hr * 12m3 = 3,840m3/일 * 72.90% = 2,800m3 반영 가능
A19: 세륜기 반영 | B19: 1대 단독 | C19: M3 | F19: =(60/1.5)*8*12*1 -> 3840 | G19: =D19/F19 -> 0 | H19: 0.729 | I19: =G19/H19 -> 0 | J19: =I19/30 -> 0
B20: 2대 병렬 | C20: M3 | F20: =F19*2 -> 7680 | G20: =D20/F20 -> 0 | H20: 0.729 | I20: =G20/H20 -> 0 | J20: =I20/30 -> 0
A22: ■ 백호우 토사상차 일 작업량 _ 표준품셈
A23: 위 치 | B23: Q | D23: q | E23: k | F23: f | G23: E | H23: Cm | I23: 일작업량(M3) (8hr 기준)
B24: 작업량(㎥/hr) | D24: 버킷 용량(㎥) | E24: 버킷 계수 | F24: 체적환산계수 | G24: 작업 효율 | H24: 싸이클 타임
B25: 3,600×q×k×f×E/Cm | D25: 1.0W | F25: 1/L | G25: 흐트러진상태 (보통) | H25: 180도 | J25: 체적변화율(L) | L25: 적용
A26: 토사, 풍화암 | D26: 1 | E26: 0.9 | F26: =ROUND(1/L26,2) -> 0.77 | G26: 0.75 | H26: 23 | I26: =ROUND(B26*8,0) -> 0 | J26: 점질토/풍화암 | K26: 1.25 ~ 1.35 | L26: 1.3
A27: 발파암 | D27: 1 | E27: 0.55 | F27: =ROUND(1/L27,2) -> 0.71 | G27: 0.45 | H27: 23 | I27: =ROUND(B27*8,0) -> 0 | J27: 연암 | K27: 1.30 ~ 1.50 | L27: 1.4
A29: ■ 덤프트럭 일 작업량 _ 표준품셈 | D29: ■ 1조 : 흙깍기(백호, 0.7W) + 집토(도저) + 상차(백호, 0.7W) 운용
A30: 공 종 | B30: 규 격 | C30: 단위 | D30: 토 공 량 | E30: 단위 생산량 | F30: 투입 조 | G30: 일생산량 (8시간/일) | H30: W.D (8시간/일) | I30: 가동율(%) : 토공사 | J30: C.D(Day) | K30: C.D(Month) | L30: 비 고
A31: 토사, 풍화암 | B31: 12 m3 / 25ton | C31: M3 | E31: =12*7*8 -> 672 | G31: =E31*F31 -> 0 | H31: =D31/G31 -> #DIV/0! | I31: 0.729 | J31: =H31/I31 -> #DIV/0! | K31: =J31/30 -> #DIV/0!
A32: 발파암 | B32: 12 m3 / 25ton | C32: M3 | E32: =12*7*8 -> 672 | G32: =E32*F32 -> 0 | I32: 0.729 | J32: =H32/I32 -> 0 | K32: =J32/30 -> 0
A33: 합 계 | C33: M3 | D33: =D31+D32 -> 0 | K33: =SUM(K31:K32) -> #DIV/0!
A35: ■ 성토 일 작업량 _ 표준품셈 | D35: ■ 1조 : 흙깍기(백호, 0.7W) + 집토(도저) + 상차(백호, 0.7W) 운용
A36: 공 종 | B36: 규 격 | C36: 단위 | D36: 토 공 량 | E36: 단위 생산량 | F36: 투입 조 | G36: 일생산량 (8시간/일) | H36: W.D (8시간/일) | I36: 가동율(%) : 토공사 | J36: C.D(Day) | K36: C.D(Month) | L36: 비 고
A37: 순성토 | C37: M3 | E37: 600 | G37: =E37*F37 -> 0 | H37: =D37/G37 -> #DIV/0! | I37: 0.729 | J37: =H37/I37 -> #DIV/0! | K37: =J37/30 -> #DIV/0!
A39: 합 계 | C39: M3 | D39: =D37+D38 -> 0 | K39: =SUM(K37:K38) -> #DIV/0!
A41: ■ 크람쉘 일 작업량 (유사 PJT 영동대로 기준 반영) | G41: ■ 버킷호이스트 일 작업량 (유사 PJT 영동대로 기준 반영)
A42: 구 분 | B42: 소요시간 | C42: 적 용 | E42: 비 고 | G42: 구 분 | I42: 소요시간 | J42: 적 용 | L42: 비 고
A43: [ 조건 ] 일반 토사 | G43: [ 조건 ] 일반 토사
A44: 버킷용적 | B44: 1.53 | E44: 50TON 크레인 | G44: 버킷용적 | I44: 13 | J44: 제작 - 15㎥ | L44: 50TON 크레인
A45: 인양높이 (m) | B45: 6 | G45: 인양높이 (m) | I45: 2m ~ 45m | J45: 30m
A46: 인양속도 (m/min) | B46: 30m/min | G46: 인양속도 (m/min) | I46: 30m/min
...

Sheet 발파암(표준발파)
A1: [공기 산출근거] 발파
A2: 공사명 : 과천 갈현초등학교 증축공사
A3: [ 기본조건 ] | K3: 2025. 07. 01
A4: * 천공기계 : 크롤러드릴 1~4대 | E4: * 화약 사용량 : 200kg/일 | I4: * 작업시간 : 8시간/일
A7: 국토부 표준발파 | B7: 구분 | C7: 단위 | D7: 미진동굴착 | E7: 정밀진동 제어발파 | F7: 진동제어발파 | H7: 일반발파 | I7: 대발파 | J7: 합계 | K7: 비고
F8: 소규모 | G8: 중규모
B9: 천공깊이 | C9: m | D9: 1.5 | E9: 2 | F9: 2.7 | G9: 3.4 | H9: 5.7 | I9: 8.7
B10: 최소저항선 | C10: m | D10: 0.7 | E10: 0.7 | F10: 1 | G10: 1.6 | H10: 2 | I10: 2.8
B11: 천공간격 | C11: m | D11: 0.7 | E11: 0.8 | F11: 1.2 | G11: 1.9 | H11: 2.4 | I11: 3
B12: 표준 지발당 장약량 | C12: kg | D12: 0.125 | E12: 0.25 | F12: 1 | G12: 3 | H12: 7.5 | I12: 20
B13: 천공경 | C13: mm | D13: Ø51 이내 | E13: Ø51 이내 | F13: Ø51 이내 | G13: Ø76 | H13: Ø76 | I13: Ø76 이상
B14: 공당 파쇄량 | C14: ㎥ | D14: =D9*D10*D11 -> 0.735 | E14: =E9*E10*E11 -> 1.12 | F14: =F9*F10*F11 -> 3.24 | G14: =G9*G10*G11 -> 10.336 | H14: =H9*H10*H11 -> 27.36 | I14: =I9*I10*I11 -> 73.08 | O14: 흙깎기/발파암/미진동 굴착 | P14: 147.5 | Q14: =D19 -> 47.04 | R14: =P14/Q14 -> 3.1356293
B15: 일일 천공수(1대) | C15: 공 | D15: =($B$26/(D$9*100))*60*8*$L15 -> 64 | E15: =($B$26/(E$9*100))*60*8*$L15 -> 48 | F15: =($B$26/(F$9*100))*60*8*$L15 -> 35.555556 | G15: =($B$26/(G$9*100))*60*8*$L15 -> 28.235294 | H15: =($B$26/(H$9*100))*60*8*$L15 -> 16.842105 | I15: =($B$26/(I$9*100))*60*8*$L15 -> 11.034483 | K15: 소형브레이커, 연암 | L15: 1 | O15: 흙깎기/발파암/정밀진동제어발파 | P15: 885 | Q15: =E19 -> 53.76 | R15: =P15/Q15 -> 16.462054
B16: 일일 천공수(2대) | C16: 공 | D16: =($B$26/(D$9*100))*60*8*$L16 -> 128 | E16: =($B$26/(E$9*100))*60*8*$L16 -> 96 | F16: =($B$26/(F$9*100))*60*8*$L16 -> 71.111111 | G16: =($B$26/(G$9*100))*60*8*$L16 -> 56.470588 | H16: =($B$26/(H$9*100))*60*8*$L16 -> 33.684211 | I16: =($B$26/(I$9*100))*60*8*$L16 -> 22.068966 | K16: 소형브레이커, 연암 | L16: 2 | O16: 흙깎기/발파암/소규모진동제어발파 | P16: 442.5 | Q16: =F19 -> 115.2 | R16: =P16/Q16 -> 3.8411458
B17: 일일 천공수(3대) | C17: 공 | D17: =($B$26/(D$9*100))*60*8*$L17 -> 192 | E17: =($B$26/(E$9*100))*60*8*$L17 -> 144 | F17: =($B$26/(F$9*100))*60*8*$L17 -> 106.66667 | G17: =($B$26/(G$9*100))*60*8*$L17 -> 84.705882 | H17: =($B$26/(H$9*100))*60*8*$L17 -> 50.526316 | I17: =($B$26/(I$9*100))*60*8*$L17 -> 33.103448 | K17: 소형브레이커, 연암 | L17: 3 | P17: =SUM(P14:P16) -> 1475
B18: 일일 천공수(4대) | C18: 공 | D18: =($B$26/(D$9*100))*60*8*$L18 -> 256 | E18: =($B$26/(E$9*100))*60*8*$L18 -> 192 | F18: =($B$26/(F$9*100))*60*8*$L18 -> 142.22222 | G18: =($B$26/(G$9*100))*60*8*$L18 -> 112.94118 | H18: =($B$26/(H$9*100))*60*8*$L18 -> 67.368421 | I18: =($B$26/(I$9*100))*60*8*$L18 -> 44.137931 | K18: 소형브레이커, 연암 | L18: 4
B19: 일일 작업량 | C19: ㎥ | D19: =D15*D14 -> 47.04 | E19: =E15*E14 -> 53.76 | F19: =F15*F14 -> 115.2 | G19: =G15*G14 -> 291.84 | H19: =H15*H14 -> 460.8 | I19: =I15*I14 -> 806.4
B20: 발파암량 | C20: ㎥ | D20: 5081.11 | E20: 38111.38 | F20: 33659.49 | G20: 3786.99 | J20: =SUM(D20:I20) -> 80638.97
B21: 소요일수 | C21: 일 | D21: =ROUNDUP(D20/D19,0) -> 109 | E21: =ROUNDUP(E20/E19,0) -> 709 | F21: =ROUNDUP(F20/F19,0) -> 293 | G21: =ROUNDUP(G20/G19,0) -> 13 | H21: =ROUNDUP(H20/H19,0) -> 0 | I21: =ROUNDUP(I20/I19,0) -> 0
A23: ■ 천공기계의 천공속도 | D23: * 천공수(공)/일
A24: 구 분 | C24: 단위 | D24: 미진동 | E24: 정밀진동 | F24: 소규모 | G24: 중규모 | H24: 일반발파 | I24: 대발파
A25: 풍화암 | B25: 27 | D25: =($B$25/(D$9*100))*60*8*$L$15 -> 86.4 | E25: =($B$25/(E$9*100))*60*8*$L$15 -> 64.8 | F25: =($B$25/(F$9*100))*60*8*$L$15 -> 48 | G25: =($B$25/(G$9*100))*60*8*$L$15 -> 38.117647 | H25: =($B$25/(H$9*100))*60*8*$L$15 -> 22.736842 | I25: =($B$25/(I$9*100))*60*8*$L$15 -> 14.896552
A26: 연암 | B26: 20 | D26: =($B$26/(D$9*100))*60*8*$L15 -> 64 | E26: =($B$26/(E$9*100))*60*8*$L15 -> 48 | F26: =($B$26/(F$9*100))*60*8*$L15 -> 35.555556 | G26: =($B$26/(G$9*100))*60*8*$L15 -> 28.235294 | H26: =($B$26/(H$9*100))*60*8*$L15 -> 16.842105 | I26: =($B$26/(I$9*100))*60*8*$L15 -> 11.034483
A27: 보통암 | B27: 16 | D27: =($B$27/(D$9*100))*60*8*$L$15 -> 51.2 | E27: =($B$27/(E$9*100))*60*8*$L$15 -> 38.4 | F27: =($B$27/(F$9*100))*60*8*$L$15 -> 28.444444 | G27: =($B$27/(G$9*100))*60*8*$L$15 -> 22.588235 | H27: =($B$27/(H$9*100))*60*8*$L$15 -> 13.473684 | I27: =($B$27/(I$9*100))*60*8*$L$15 -> 8.8275862
A28: 경암 | B28: 12 | D28: =($B$28/(D$9*100))*60*8*$L$15 -> 38.4 | E28: =($B$28/(E$9*100))*60*8*$L$15 -> 28.8 | F28: =($B$28/(F$9*100))*60*8*$L$15 -> 21.333333 | G28: =($B$28/(G$9*100))*60*8*$L$15 -> 16.941176 | H28: =($B$28/(H$9*100))*60*8*$L$15 -> 10.105263 | I28: =($B$28/(I$9*100))*60*8*$L$15 -> 6.6206897

Sheet 철골공사, 데크플레이트
A1: [공기 산출근거] 철골공사 | J1: 45839
A2: 공사명 : 인천 뮤지엄파크 신축공사
A5: 표준품셈
A6: 1. 철골작업량 : 1-2-2 철골세우기 장비의 작업능력 | G6: 2. 데크플레이트 작업량 : 1-3-3 데크플레이트 설치
A7: * 크레인 / 트러스, 거더류 / 15ton 적용 | G7: * 철골공, 용접공, 특별인부 / 0.05인/m2 = 20.0m2/일 적용
