Workbook
Name _: #REF!
Name _: #REF!
Name _: #REF!
Name _: #REF!
Name __: #REF!
Name __: #REF!
Name __: #REF!
Name ___: #REF!
Name ___: #REF!
Name ___: #REF!
Name ____: #REF!
Name ____: #REF!
Name _____: #REF!
Name _____: #REF!
Name ______: #REF!
Name ______: #REF!
Name _______: #REF!
Name _______: #REF!
Name __________: #REF!
Name __________: #REF!
Name _____________0: #REF!
Name _____________0: #REF!
Name _____________11: #REF!
Name _____________11: #REF!
Name _____________12: #REF!
Name _____________12: #REF!
Name __________0: #REF!
Name __________0: #REF!
Name __________11: #REF!
Name __________11: #REF!
Name __________12: #REF!
Name __________12: #REF!
Name _________0: #REF!
Name _________0: #REF!
Name _________10: #REF!
Name _________10: #REF!
Name _________11: #REF!
Name _________11: #REF!
Name _________12: #REF!
Name _________12: #REF!
Name ________0: #REF!
Name ________0: #REF!
Name ________10: #REF!
Name ________10: #REF!
Name ________11: #REF!
Name ________11: #REF!
Name ________12: #REF!
Name ________12: #REF!
Name _______0: #REF!
Name _______0: #REF!
Name ______0: #REF!
Name ______0: #REF!
Name ______11: #REF!
Name ______11: #REF!
Name ______12: #REF!
Name ______12: #REF!
Name ______NMB96: #REF!
Name _____0: #REF!
Name _____0: #REF!
Name _____10: #REF!

Sheet 설계서
A1: 설계년월일 | C1: 2025년 06 월 일 설계 | F1: 설 계 자 | I1: 심 사 자 | L1: 담 | O1: 과 | R1: 비
L2: 당 | O2: 장 | R2: 고
A3: 설 계 서
D4: 공 사 명 | G4: : | I4: =원가제비율!D3 -> 대화면도시재생사업청학당조성공사기본및실시설
D5: 총 공 사 비 | G5: : | H5: =P18 -> 3.091637e+09 | K5: ="(금 "&NUMBERSTRING( P18,1)&"원)" -> (금 삼십억구천일백육십삼만칠천원)
D6: 도 급 공 사 비 | G6: : | H6: =I18 -> 2.525321e+09 | K6: ="(금 "&NUMBERSTRING( I18,1)&"원)" -> (금 이십오억이천오백삼십이만일천원)
D7: 공 급 가 액 | G7: : | H7: =D18 -> 2.2957464e+09 | K7: ="(금 "&NUMBERSTRING( D18,1)&"원)" -> (금 이십이억구천오백칠십사만육천삼백육십사원)
D8: 부 가 가 치 세 | G8: : | H8: =G18 -> 2.2957464e+08 | K8: ="(금 "&NUMBERSTRING( G18,1)&"원)" -> (금 이억이천구백오십칠만사천육백삼십육원)
D9: 관 급 자 재 비 | G9: : | H9: =L18 -> 563849000 | K9: ="(금 "&NUMBERSTRING( L18,1)&"원)" -> (금 오억육천삼백팔십사만구천원)
D10: 기 타 경 비 | G10: : | H10: =N18 -> 2467000 | K10: ="(금 "&NUMBERSTRING( N18,1)&"원)" -> (금 이백사십육만칠천원)
A12: 구 분 | D12: 공 급 가 액 | G12: 부 가 세 | I12: 도 급 액 | L12: 관급자재비 | N12: 기타경비 | P12: 총 공 사 비 | T12: (%)
A13: 건축공사(건축,토공,기계) | D13: ='원가계산서(건축분야총괄)'!H34 -> 1.9673791e+09 | G13: ='원가계산서(건축분야총괄)'!H35 -> 1.9673791e+08 | I13: ='원가계산서(건축분야총괄)'!H36 -> 2.164117e+09 | L13: ='원가계산서(건축분야총괄)'!H40+'원가계산서(건축분야총괄)'!H41 -> 512734000 | N13: ='원가계산서(건축분야총괄)'!H38 -> 0 | P13: =I13+L13+N13 -> 2.676851e+09 | T13: =P13/P18*100 -> 86.583612
A14: 전 기 공 사 | D14: =D28 -> 3.2836727e+08 | G14: =G28 -> 32836727 | I14: =I28 -> 3.61204e+08 | L14: =L28+N28 -> 51115000 | N14: =P28 -> 2467000 | P14: =R28 -> 4.14786e+08 | T14: =P14/P18*100 -> 13.416388
G15: =D15*10% -> 0 | I15: =D15+G15 -> 0 | P15: =I15+L15+N15 -> 0 | T15: =P15/P18*100 -> 0
A18: 총 계 | D18: =SUM(D13:D17)-1 -> 2.2957464e+09 | G18: =SUM(G13:G17) -> 2.2957464e+08 | I18: =SUM(I13:I17) -> 2.525321e+09 | L18: =SUM(L13:L17) -> 563849000 | N18: =SUM(N13:N17) -> 2467000 | P18: =SUM(P13:P17) -> 3.091637e+09 | T18: =SUM(T13:T17) -> 100
P19: 2929515820
A24: 구분 | D24: 공급가액 | G24: 부가세 | I24: 도급액 | L24: 관급(도급) | N24: 관급(관급) | P24: 한전인입비 | R24: 합 계
A25: 전기공사 | D25: =210169694-663/1.1 -> 2.1016909e+08 | G25: =D25*0.1 -> 21016909 | I25: =D25+G25 -> 2.31186e+08 | L25: =20952354+646 -> 20953000 | P25: =1656600+811000-600 -> 2467000 | R25: =I25+L25+N25+P25 -> 2.54606e+08
A26: 통신공사 | D26: =48965044-548/1.1 -> 48964546 | G26: =D26*10% -> 4896454.6 | I26: =D26+G26 -> 53861000 | N26: 30162000 | R26: =I26+L26+N26+P26 -> 84023000
A27: 소방공사 | D27: =69234293-722/1.1 -> 69233637 | G27: =D27*10% -> 6923363.7 | I27: =D27+G27 -> 76157000 | R27: =I27+L27+N27+P27 -> 76157000
A28: 합계 | D28: =SUM(D25:D27) -> 3.2836727e+08 | G28: =SUM(G25:G27) -> 32836727 | I28: =SUM(I25:I27)-1 -> 3.61204e+08 | L28: =SUM(L25:L27) -> 20953000 | N28: =SUM(N25:N27) -> 30162000 | P28: =SUM(P25:P27) -> 2467000 | R28: =I28+L28+N28+P28 -> 4.14786e+08
N30: =L28+N28 -> 51115000

Sheet 총괄집계표
A1: =원가제비율!D3 -> 대화면도시재생사업청학당조성공사기본및실시설
A2: (총 괄 집 계 표)
A4: 구분 | B4: 도급액 | C4: 관급(도급자설치) | D4: 관급(관급자설치) | E4: 시설분담금 | F4: 합계
A5: 건축공사 | B5: ='원가계산서(건축)'!H39 -> 1.995656e+09 | C5: ='원가계산서(건축)'!H40 -> 282492000 | D5: ='원가계산서(건축)'!H41 -> 176354000 | F5: =B5+C5+D5+E5 -> 2.454502e+09 | G5: =F5/$F$15 -> 0.7928649
A6: 토목공사 | B6: ='원가계산서(토목)'!H39 -> 75055000 | C6: ='원가계산서(토목)'!H40 -> 10958000 | D6: ='원가계산서(토목)'!H41 -> 0 | F6: =B6+C6+D6+E6 -> 86013000 | G6: =F6/$F$15 -> 0.027784328
A7: 조경공사 | B7: ='원가계산서(조경)'!H38 -> 0 | C7: ='원가계산서(조경)'!H39 -> 0 | D7: ='원가계산서(조경)'!H40 -> 0 | F7: =B7+C7+D7+E7 -> 0
A8: 기계설비공사 | B8: ='원가계산서(기계)'!H39 -> 97507000 | C8: ='원가계산서(기계)'!H40 -> 0 | D8: ='원가계산서(기계)'!H41 -> 42930000 | F8: =B8+C8+D8+E8 -> 1.40437e+08 | G8: =F8/$F$15 -> 0.045364627
B9: ='원가계산서(폐기물)'!H35 -> 0 | F9: =B9+C9+D9+E9 -> 0
A10: 소계 | B10: =SUM(B5:B9) -> 2.168218e+09 | C10: =SUM(C5:C9) -> 293450000 | D10: =SUM(D5:D9) -> 219284000 | E10: =SUM(E5:E9) -> 0 | F10: =SUM(F5:F9) -> 2.680952e+09 | G10: =F10/$F$15 -> 0.86601386
A11: 전기공사 | B11: =설계서!I25 -> 2.31186e+08 | C11: =설계서!L25 -> 20953000 | D11: =설계서!N25 -> 0 | E11: =설계서!P25 -> 2467000 | F11: =B11+C11+D11+E11 -> 2.54606e+08 | G11: =F11/$F$15 -> 0.08224404
A12: 통신설비공사 | B12: =설계서!I26 -> 53861000 | D12: =설계서!N26 -> 30162000 | F12: =B12+C12+D12+E12 -> 84023000 | G12: =F12/$F$15 -> 0.027141509
A13: 소방설비공사 | B13: =설계서!I27 -> 76157000 | F13: =B13+C13+D13+E13 -> 76157000 | G13: =F13/$F$15 -> 0.024600596
A14: 소계 | B14: =B11+B12+B13-1 -> 3.61204e+08 | C14: =C11+C12+C13 -> 20953000 | D14: =D11+D12+D13 -> 30162000 | E14: =E11+E12+E13 -> 2467000 | F14: =F11+F12+F13-1 -> 4.14786e+08 | G14: =F14/$F$15 -> 0.13398614
A15: 총계 | B15: =B10+B14 -> 2.529422e+09 | C15: =C10+C14 -> 314403000 | D15: =D10+D14 -> 249446000 | E15: =E10+E14 -> 2467000 | F15: =F10+F14 -> 3.095738e+09 | G15: =F15/$F$15 -> 1
E18: 설계예산 | F18: =원가제비율!D6 -> 0
E19: 조정금액 | F19: =F18-F15 -> -3.095738e+09

Sheet 원가계산서(건축분야총괄)
A1: 공 사 원 가 계 산 서
A2: =원가제비율!D3 -> 대화면도시재생사업청학당조성공사기본및실시설 | G2: 공사기간 : | H2: =원가제비율!D5 -> 7~12개월이하, 2025.04.01 제비율
A3: 구 분 | E3: 산 출 방 법 | H3: 금 액 | I3: 비 고
A5: 1. 순공사 원가 | E5: [가+나+다] | H5: =H6+H8+H11 -> 1.6828565e+09
B6: 가. 재료비 | H6: =H7 -> 560141843
C7: 가-1. 직접재료비 | H7: ='원가계산서(건+토+기)'!L7 -> 560141843
B8: 나. 노무비 | H8: =H9+H10 -> 7.6254867e+08
C9: 나-1. 직접노무비 | H9: ='원가계산서(건+토+기)'!L9 -> 663662901
C10: 나-2. 간접노무비 | E10: [나1] 의 | G10: =원가제비율!G16 -> 0.149 | H10: =H9*G10 -> 98885772
B11: 다. 경비 | H11: =H12+H13+H14+H15+H16+H17+H18+H19+H23+H24+H25+H26+H27+H28+H29 -> 3.6016597e+08
C12: 다-1. 산출경비 | H12: ='원가계산서(건+토+기)'!L12 -> 113799309
C13: 다-2. 산재보험료 | E13: [나] 의 | G13: =원가제비율!G19 -> 0.0356 | H13: ='원가계산서(건+토+기)'!L13 -> 27146733
C14: 다-3. 고용보험료 | E14: [나] 의 | G14: =원가제비율!G20 -> 0.0101 | H14: =H8*G14 -> 7701741.6
C15: 다-4. 국민건강보험료 | E15: [나1] 의 | G15: =원가제비율!G21 -> 0.03545 | H15: =H9*G15 -> 23526850
C16: 다-5. 노인장기요양보험료 | E16: [다4] 의 | G16: =원가제비율!G22 -> 0.1295 | H16: =INT(H15*G16) -> 3046727
C17: 다-6. 국민연금보험료 | E17: [나1] 의 | G17: =원가제비율!G23 -> 0.045 | H17: =H9*G17 -> 29864831
C18: 다-7. 퇴직공제부금비 | E18: [나1] 의 | G18: =원가제비율!G24 -> 0.023 | H18: =H9*G18 -> 15264247
C19: 다-8. 산업안전보건관리비 | E19: ※ 관급포함시 : ⓑ와ⓒ 비교후 적은금액 적용 | H19: =SMALL(H21:H22,COUNTIF(H21:H22,0)+1) -> 38310166
D20: ⓐ.일반의경우 | E20: [가+나1] 의 | F20: =원가제비율!F26 -> 0.0228 | G20: =원가제비율!G26 -> 4325000 | H20: =(H7+H9)*F20+G20 -> 32227748
D21: ⓑ.ⓐ의 1.2배 | H21: =H20*1.2 -> 38673298
D22: ⓒ.관급자재대 포함 | E22: [가+나1+관급자재대] 의 | F22: =원가제비율!F28 -> 0.0228 | G22: =원가제비율!G28 -> 4325000 | H22: =(H6+H9+H40/1.1)*F22+G22 -> 38310166
C23: 다-9. 기타경비 | E23: [가+나] 의 | G23: =원가제비율!G29 -> 0.048 | H23: =(H6+H8)*G23 -> 63489145
C24: 다-10. 공사이행보증서 발급수수료 | E24: ([가+나1+다1] 의-140억원*0.019%)*공기(년) | H24: ='원가계산서(건+토+기)'!L24 -> 0
C25: 다-11. 하도급 대금 지급보증서 발급수수료 | E25: [가+나1+다1] 의 | G25: =원가제비율!G31 -> 0.00081 | H25: =(H6+H9+H12)*G25 -> 1083459.3
C26: 다-12. 건설기계대여대금지급보증서발급금액 | E26: [가+나1+다1] 의 | G26: =원가제비율!G32 -> 0.0007 | H26: =(H6+H9+H12)*G26 -> 936322.84
C27: 다-13. 환경보전비 | E27: [가+나1+다1] 의 | G27: =원가제비율!G33 -> 0.005 | H27: =(H6+H9+H12)*G27 -> 6688020.3
C28: 다-14. 품질관리비 | H28: ='원가계산서(건+토+기)'!L28 -> 7798410
C29: 다-15. 안전관리비 | H29: ='원가계산서(건+토+기)'!L29 -> 21510009
A30: 2. 일 반 관 리 비 | E30: [1] 의 | G30: =원가제비율!G36 -> 0.06 | H30: =H5*G30 -> 1.0097139e+08
A31: 3. 이 윤 | E31: [나+다+2]의 | G31: =원가제비율!G37 -> 0.15 | H31: =(H8+H11+H30)*G31-1858/1.1 -> 1.8355122e+08
A32: 4. T. A. B 공 사 | H32: ='원가계산서(건+토+기)'!L32 -> 0
A33: 5. 시공 상세도 작성비 | H33: ='원가계산서(건+토+기)'!L33 -> 0
A34: 6. 공 급 가 액 | E34: [1+2+3+4+5] | H34: =(H5+H30+H31+H32+H33) -> 1.9673791e+09
A35: 7. 부 가 가 치 세 | E35: [6]의 | G35: 0.1 | H35: =H34*G35 -> 1.9673791e+08
A36: 8. 도 급 액 | E36: [6+7] | H36: =H34+H35 -> 2.164117e+09
A37: 9. 건설 폐기물 처리비 | H37: ='원가계산서(건+토+기)'!L37 -> 4100999.7
A38: 10. 시 설 분 담 금 | H38: =공종별총괄표!L28 -> 0
A39: 조 사 금 액 | H39: =H36+H37+H38 -> 2.168218e+09
A40: 관급자재대(도급자관급) | H40: ='원가계산서(건+토+기)'!L40 -> 293450000
A41: 관급자재대(관급자관급) | H41: ='원가계산서(건+토+기)'!L41 -> 219284000
...

Sheet 원가계산서(건+토+기)
A1: 공 사 원 가 계 산 서
A2: =원가제비율!D3 -> 대화면도시재생사업청학당조성공사기본및실시설 | K2: 공사기간 : | L2: =원가제비율!D5 -> 7~12개월이하, 2025.04.01 제비율
A3: 구 분 | E3: 산 출 방 법 | H3: 건 축 | I3: 토 목 | J3: 조 경 | K3: 기 계 | L3: 합 계 | M3: 비 고
A5: 1. 순공사 원가 | E5: [가+나+다] | H5: =H6+H8+H11 -> 1.5464205e+09 | I5: =I6+I8+I11 -> 57528998 | J5: =J6+J8+J11 -> 0 | K5: =K6+K8+K11 -> 78906950 | L5: =H5+I5+J5+K5 -> 1.6828565e+09
B6: 가. 재료비 | H6: =H7 -> 491423918 | I6: =I7 -> 18422520 | J6: =J7 -> 0 | K6: =K7 -> 50295405 | L6: =H6+I6+J6+K6 -> 560141843
C7: 가-1. 직접재료비 | H7: ='원가계산서(건축)'!H7 -> 491423918 | I7: ='원가계산서(토목)'!H7 -> 18422520 | J7: ='원가계산서(조경)'!H7 -> 0 | K7: ='원가계산서(기계)'!H7 -> 50295405 | L7: =H7+I7+J7+K7 -> 560141843
B8: 나. 노무비 | H8: =H9+H10 -> 7.3016151e+08 | I8: =I9+I10 -> 12052357 | J8: =J9+J10 -> 0 | K8: =K9+K10 -> 20334804 | L8: =H8+I8+J8+K8 -> 7.6254867e+08
C9: 나-1. 직접노무비 | H9: ='원가계산서(건축)'!H9 -> 635475641 | I9: ='원가계산서(토목)'!H9 -> 10489432 | J9: ='원가계산서(조경)'!H9 -> 0 | K9: ='원가계산서(기계)'!H9 -> 17697828 | L9: =H9+I9+J9+K9 -> 663662901
C10: 나-2. 간접노무비 | E10: [나1] 의 | G10: =원가제비율!G16 -> 0.149 | H10: =H9*G10 -> 94685871 | I10: =I9*G10 -> 1562925.4 | J10: =J9*G10 -> 0 | K10: =K9*G10 -> 2636976.4 | L10: =H10+I10+J10+K10 -> 98885772
B11: 다. 경비 | H11: =H12+H13+H14+H15+H16+H17+H18+H19+H23+H24+H25+H26+H27+H28+H29 -> 3.2483511e+08 | I11: =I12+I13+I14+I15+I16+I17+I18+I19+I23+I24+I25+I26+I27+I28+I29 -> 27054120 | J11: =J12+J13+J14+J15+J16+J17+J18+J19+J23+J24+J25+J26+J27+J28+J29 -> 0 | K11: =K12+K13+K14+K15+K16+K17+K18+K19+K23+K24+K25+K26+K27+K28+K29 -> 8276740.3 | L11: =H11+I11+J11+K11 -> 3.6016597e+08
C12: 다-1. 산출경비 | H12: ='원가계산서(건축)'!H12 -> 103491491 | I12: ='원가계산서(토목)'!H12 -> 10255934 | J12: ='원가계산서(조경)'!H12 -> 0 | K12: ='원가계산서(기계)'!H12 -> 51884 | L12: =H12+I12+J12+K12 -> 113799309
C13: 다-2. 산재보험료 | E13: [나] 의 | G13: =원가제비율!G19 -> 0.0356 | H13: ='원가계산서(건축)'!H13 -> 25993750 | I13: ='원가계산서(토목)'!H13 -> 429063.92 | J13: ='원가계산서(조경)'!H13 -> 0 | K13: ='원가계산서(기계)'!H13 -> 723919.04 | L13: =H13+I13+J13+K13 -> 27146733
C14: 다-3. 고용보험료 | E14: [나] 의 | G14: =원가제비율!G20 -> 0.0101 | H14: ='원가계산서(건축)'!H14 -> 7374631.3 | I14: ='원가계산서(토목)'!H14 -> 121728.81 | J14: ='원가계산서(조경)'!H14 -> 0 | K14: ='원가계산서(기계)'!H14 -> 205381.52 | L14: =H14+I14+J14+K14 -> 7701741.6
C15: 다-4. 국민건강보험료 | E15: [나1] 의 | G15: =원가제비율!G21 -> 0.03545 | H15: ='원가계산서(건축)'!H15 -> 22527611 | I15: ='원가계산서(토목)'!H15 -> 371850.36 | J15: ='원가계산서(조경)'!H15 -> 0 | K15: ='원가계산서(기계)'!H15 -> 627388 | L15: =H15+I15+J15+K15 -> 23526850
C16: 다-5. 노인장기요양보험료 | E16: [다4] 의 | G16: =원가제비율!G22 -> 0.1295 | H16: ='원가계산서(건축)'!H16 -> 2917325 | I16: ='원가계산서(토목)'!H16 -> 48154 | J16: ='원가계산서(조경)'!H16 -> 0 | K16: ='원가계산서(기계)'!H16 -> 81246 | L16: =H16+I16+J16+K16 -> 3046725
C17: 다-6. 국민연금보험료 | E17: [나1] 의 | G17: =원가제비율!G23 -> 0.045 | H17: ='원가계산서(건축)'!H17 -> 28596404 | I17: ='원가계산서(토목)'!H17 -> 472024.44 | J17: ='원가계산서(조경)'!H17 -> 0 | K17: ='원가계산서(기계)'!H17 -> 796402.26 | L17: =H17+I17+J17+K17 -> 29864831
C18: 다-7. 퇴직공제부금비 | E18: [나1] 의 | G18: =원가제비율!G24 -> 0.023 | H18: ='원가계산서(건축)'!H18 -> 14615940 | I18: ='원가계산서(토목)'!H18 -> 241256.94 | J18: ='원가계산서(조경)'!H18 -> 0 | K18: ='원가계산서(기계)'!H18 -> 407050.04 | L18: =H18+I18+J18+K18 -> 15264247
C19: 다-8. 산업안전보건관리비 | E19: ※ 관급포함시 : ⓑ와ⓒ 비교후 적은금액 적용 | H19: ='원가계산서(건축)'!H19 -> 35873599 | I19: ='원가계산서(토목)'!H19 -> 886321.96 | J19: ='원가계산서(조경)'!H19 -> 0 | K19: ='원가계산서(기계)'!H19 -> 1550245.7 | L19: =H19+I19+J19+K19 -> 38310166
D20: ⓐ.일반의경우 | E20: [가+나1] 의 | F20: =원가제비율!F26 -> 0.0228 | G20: =원가제비율!G26 -> 4325000 | H20: ='원가계산서(건축)'!H20 -> 30018310 | I20: ='원가계산서(토목)'!H20 -> 659192.51 | J20: ='원가계산서(조경)'!H20 -> 0 | K20: ='원가계산서(기계)'!H20 -> 1550245.7 | L20: =H20+I20+J20+K20 -> 32227748
D21: ⓑ.ⓐ의 1.2배 | H21: ='원가계산서(건축)'!H21 -> 36021972 | I21: ='원가계산서(토목)'!H21 -> 791031.01 | J21: ='원가계산서(조경)'!H21 -> 0 | K21: ='원가계산서(기계)'!H21 -> 1860294.9 | L21: =H21+I21+J21+K21 -> 38673298
D22: ⓒ.관급자재대 포함 | E22: [가+나1+관급자재대] 의 | F22: =원가제비율!F28 -> 0.0228 | G22: =원가제비율!G28 -> 4325000 | H22: ='원가계산서(건축)'!H22 -> 35873599 | I22: ='원가계산서(토목)'!H22 -> 886321.96 | J22: ='원가계산서(조경)'!H22 -> 0 | K22: ='원가계산서(기계)'!H22 -> 1550245.7 | L22: =H22+I22+J22+K22 -> 38310166
C23: 다-9. 기타경비 | E23: [가+나] 의 | G23: =원가제비율!G29 -> 0.048 | H23: ='원가계산서(건축)'!H23 -> 58636101 | I23: ='원가계산서(토목)'!H23 -> 1462794.1 | J23: ='원가계산서(조경)'!H23 -> 0 | K23: ='원가계산서(기계)'!H23 -> 3390250 | L23: =H23+I23+J23+K23 -> 63489145
C24: 다-10. 공사이행보증서 발급수수료 | E24: ([가+나1+다1] 의-140억원*0.019%)*공기(년) | H24: ='원가계산서(건축)'!H24 -> 0 | I24: ='원가계산서(토목)'!H24 -> 0 | J24: ='원가계산서(조경)'!H24 -> 0 | K24: ='원가계산서(기계)'!H24 -> 0 | L24: =H24+I24+J24+K24 -> 0
C25: 다-11. 하도급 대금 지급보증서 발급수수료 | E25: [가+나1+다1] 의 | G25: =원가제비율!G31 -> 0.00081 | H25: ='원가계산서(건축)'!H25 -> 996616.75 | I25: ='원가계산서(토목)'!H25 -> 31725.988 | J25: ='원가계산서(조경)'!H25 -> 0 | K25: ='원가계산서(기계)'!H25 -> 55116.545 | L25: =H25+I25+J25+K25 -> 1083459.3
C26: 다-12. 건설기계대여대금지급보증서발급금액 | E26: [가+나1+다1] 의 | G26: =원가제비율!G32 -> 0.0007 | H26: ='원가계산서(건축)'!H26 -> 861273.73 | I26: ='원가계산서(토목)'!H26 -> 27417.52 | J26: ='원가계산서(조경)'!H26 -> 0 | K26: ='원가계산서(기계)'!H26 -> 47631.582 | L26: =H26+I26+J26+K26 -> 936322.84
C27: 다-13. 환경보전비 | E27: [가+나1+다1] 의 | G27: =원가제비율!G33 -> 0.005 | H27: ='원가계산서(건축)'!H27 -> 6151955.2 | I27: ='원가계산서(토목)'!H27 -> 195839.43 | J27: ='원가계산서(조경)'!H27 -> 0 | K27: ='원가계산서(기계)'!H27 -> 340225.59 | L27: =H27+I27+J27+K27 -> 6688020.3
C28: 다-14. 품질관리비 | H28: ='원가계산서(건축)'!H28 -> 7798410 | I28: ='원가계산서(토목)'!H28 -> 0 | J28: ='원가계산서(조경)'!H28 -> 0 | K28: ='원가계산서(기계)'!H28 -> 0 | L28: =H28+I28+J28+K28 -> 7798410
C29: 다-15. 안전관리비 | H29: ='원가계산서(건축)'!H29 -> 9000000 | I29: ='원가계산서(토목)'!H29 -> 12510009 | J29: ='원가계산서(조경)'!H29 -> 0 | K29: ='원가계산서(기계)'!H29 -> 0 | L29: =H29+I29+J29+K29 -> 21510009
A30: 2. 일 반 관 리 비 | E30: [1] 의 | G30: =원가제비율!G36 -> 0.06 | H30: ='원가계산서(건축)'!H30 -> 92785232 | I30: ='원가계산서(토목)'!H30 -> 3451739.9 | J30: ='원가계산서(조경)'!H30 -> 0 | K30: ='원가계산서(기계)'!H30 -> 4734417 | L30: =H30+I30+J30+K30 -> 1.0097139e+08
A31: 3. 이 윤 | E31: [나+다+2]의 | G31: =원가제비율!G37 -> 0.15 | H31: ='원가계산서(건축)'!H31 -> 1.7216696e+08 | I31: ='원가계산서(토목)'!H31 -> 6382899 | J31: ='원가계산서(조경)'!H31 -> 0 | K31: ='원가계산서(기계)'!H31 -> 5001360.6 | L31: =H31+I31+J31+K31 -> 1.8355122e+08
A32: 4. T. A. B 공 사 | H32: ='원가계산서(건축)'!H32 -> 0 | I32: ='원가계산서(토목)'!H32 -> 0 | J32: ='원가계산서(조경)'!H32 -> 0 | K32: ='원가계산서(기계)'!H32 -> 0 | L32: =H32+I32+J32+K32 -> 0
A33: 5. 시공 상세도 작성비 | H33: ='원가계산서(건축)'!H33 -> 0 | I33: ='원가계산서(토목)'!H33 -> 0 | K33: ='원가계산서(기계)'!H33 -> 0 | L33: =H33+I33+J33+K33 -> 0
A34: 6. 공 급 가 액 | E34: [1+2+3+4+5] | H34: ='원가계산서(건축)'!H34 -> 1.8113727e+09 | I34: ='원가계산서(토목)'!H34 -> 67363637 | J34: ='원가계산서(조경)'!H33 -> 0 | K34: ='원가계산서(기계)'!H34 -> 88642727 | L34: =H34+I34+J34+K34 -> 1.9673791e+09
A35: 7. 부 가 가 치 세 | E35: [6]의 | G35: 0.1 | H35: ='원가계산서(건축)'!H35 -> 1.8113727e+08 | I35: ='원가계산서(토목)'!H35 -> 6736363.7 | J35: ='원가계산서(조경)'!H34 -> 0 | K35: ='원가계산서(기계)'!H35 -> 8864272.7 | L35: =H35+I35+J35+K35 -> 1.9673791e+08
A36: 8. 도 급 액 | E36: [6+7] | H36: ='원가계산서(건축)'!H36 -> 1.99251e+09 | I36: ='원가계산서(토목)'!H36 -> 74100000 | J36: ='원가계산서(조경)'!H35 -> 0 | K36: ='원가계산서(기계)'!H36 -> 97507000 | L36: =H36+I36+J36+K36 -> 2.164117e+09
A37: 9. 건설 폐기물 처리비 | H37: ='원가계산서(건축)'!H37 -> 3145999.7 | I37: ='원가계산서(토목)'!H37 -> 955000 | J37: ='원가계산서(조경)'!H36 -> 0 | K37: ='원가계산서(기계)'!H37 -> 0 | L37: =H37+I37+J37+K37 -> 4100999.7
A38: 10. 시 설 분 담 금 | H38: ='원가계산서(건축)'!H38 -> 0 | I38: ='원가계산서(토목)'!H38 -> 0 | J38: ='원가계산서(조경)'!H37 -> 0 | K38: ='원가계산서(기계)'!H38 -> 0 | L38: =H38+I38+J38+K38 -> 0
A39: 조 사 금 액 | H39: =H36+H37+H38+1 -> 1.995656e+09 | I39: =I36+I37+I38 -> 75055000 | J39: =J36+J37+J38 -> 0 | K39: =K36+K37+K38 -> 97507000 | L39: =L36+L37+L38+1 -> 2.168218e+09
A40: 관급자재대(도급자관급) | H40: ='원가계산서(건축)'!H40 -> 282492000 | I40: ='원가계산서(토목)'!H40 -> 10958000 | J40: ='원가계산서(조경)'!H39 -> 0 | K40: ='원가계산서(기계)'!H40 -> 0 | L40: =H40+I40+J40+K40 -> 293450000
A41: 관급자재대(관급자관급) | H41: ='원가계산서(건축)'!H41 -> 176354000 | I41: ='원가계산서(토목)'!H41 -> 0 | J41: ='원가계산서(조경)'!H40 -> 0 | K41: ='원가계산서(기계)'!H41 -> 42930000 | L41: =H41+I41+J41+K41 -> 219284000
...

Sheet 원가계산서(건축)
A1: 공 사 원 가 계 산 서
A2: =원가제비율!D3 -> 대화면도시재생사업청학당조성공사기본및실시설 | G2: 공사기간 : | H2: =원가제비율!D5 -> 7~12개월이하, 2025.04.01 제비율
A3: 구 분 | E3: 산 출 방 법 | H3: 금 액 | I3: 비 고
A5: 1. 순공사 원가 | E5: [가+나+다] | H5: =H6+H8+H11 -> 1.5464205e+09
B6: 가. 재료비 | H6: =H7 -> 491423918
C7: 가-1. 직접재료비 | H7: =공종별총괄표!F6 -> 491423918
B8: 나. 노무비 | H8: =H9+H10 -> 7.3016151e+08
C9: 나-1. 직접노무비 | H9: =공종별총괄표!H6 -> 635475641
C10: 나-2. 간접노무비 | E10: [나1] 의 | G10: =원가제비율!G16 -> 0.149 | H10: =H9*G10 -> 94685871
B11: 다. 경비 | H11: =H12+H13+H14+H15+H16+H17+H18+H19+H23+H24+H25+H26+H27+H28+H29 -> 3.2483511e+08
C12: 다-1. 산출경비 | H12: =공종별총괄표!J6 -> 103491491
C13: 다-2. 산재보험료 | E13: [나] 의 | G13: =원가제비율!G19 -> 0.0356 | H13: =H8*G13 -> 25993750
C14: 다-3. 고용보험료 | E14: [나] 의 | G14: =원가제비율!G20 -> 0.0101 | H14: =H8*G14 -> 7374631.3
C15: 다-4. 국민건강보험료 | E15: [나1] 의 | G15: =원가제비율!G21 -> 0.03545 | H15: =H9*G15 -> 22527611
C16: 다-5. 노인장기요양보험료 | E16: [다4] 의 | G16: =원가제비율!G22 -> 0.1295 | H16: =INT(H15*G16) -> 2917325
C17: 다-6. 국민연금보험료 | E17: [나1] 의 | G17: =원가제비율!G23 -> 0.045 | H17: =H9*G17 -> 28596404
C18: 다-7. 퇴직공제부금비 | E18: [나1] 의 | G18: =원가제비율!G24 -> 0.023 | H18: =H9*G18 -> 14615940
C19: 다-8. 산업안전보건관리비 | E19: ※ 관급포함시 : ⓑ와ⓒ 비교후 적은금액 적용 | H19: =H22 -> 35873599 | K19: 건축분야총괄에 따름
D20: ⓐ.일반의경우 | E20: [가+나1] 의 | F20: =원가제비율!F26 -> 0.0228 | G20: =원가제비율!G26 -> 4325000 | H20: =(H7+H9)*F20+G20 -> 30018310
D21: ⓑ.ⓐ의 1.2배 | H21: =H20*1.2 -> 36021972
D22: ⓒ.관급자재대 포함 | E22: [가+나1+관급자재대] 의 | F22: =원가제비율!F28 -> 0.0228 | G22: =원가제비율!G28 -> 4325000 | H22: =(H6+H9+H40/1.1)*F22+G22 -> 35873599
C23: 다-9. 기타경비 | E23: [가+나] 의 | G23: =원가제비율!G29 -> 0.048 | H23: =(H6+H8)*G23 -> 58636101
C24: 다-10. 공사이행보증서 발급수수료 | E24: ([가+나1+다1] 의-140억원*0.019%)*공기(년)
C25: 다-11. 하도급 대금 지급보증서 발급수수료 | E25: [가+나1+다1] 의 | G25: =원가제비율!G31 -> 0.00081 | H25: =(H6+H9+H12)*G25 -> 996616.75
C26: 다-12. 건설기계대여대금지급보증서발급금액 | E26: [가+나1+다1] 의 | G26: =원가제비율!G32 -> 0.0007 | H26: =(H6+H9+H12)*G26 -> 861273.73
C27: 다-13. 환경보전비 | E27: [가+나1+다1] 의 | G27: =원가제비율!G33 -> 0.005 | H27: =(H6+H9+H12)*G27 -> 6151955.2
C28: 다-14. 품질관리비 | H28: =공종별집계표!L33 -> 7798410
C29: 다-15. 안전관리비 | H29: =공종별집계표!L35 -> 9000000
A30: 2. 일 반 관 리 비 | E30: [1] 의 | G30: =원가제비율!G36 -> 0.06 | H30: =H5*G30 -> 92785232
A31: 3. 이 윤 | E31: [나+다+2]의 | G31: =원가제비율!G37 -> 0.15 | H31: =(H8+H11+H30)*G31-352/1.1 -> 1.7216696e+08 | L31: 0.036 | M31: <-추정가격에 따라 변경
A32: 4. T. A. B 공 사
A33: 5. 시공 상세도 작성비
A34: 6. 공 급 가 액 | E34: [1+2+3+4+5] | H34: =(H5+H30+H31+H32+H33) -> 1.8113727e+09 | K34: 주휴수당 | L34: =H9*L31*1.4 -> 32027972
A35: 7. 부 가 가 치 세 | E35: [6]의 | G35: 0.1 | H35: =H34*G35 -> 1.8113727e+08 | K35: 고용개선장려금 | L35: =H9*L31*10% -> 2287712.3
A36: 8. 도 급 액 | E36: [6+7] | H36: =H34+H35 -> 1.99251e+09 | K36: 국민연금,건강보혐료지원 | L36: =H9*O37%*20% -> 10078644 | M36: 건강보험료 | N36: 연금보험료 | O36: 합계
A37: 9. 건설 폐기물 처리비 | H37: =공종별총괄표!L24*1.1-569 -> 3145999.7 | I37: 부가가치세포함 | L37: =SUM(L34:L36) -> 44394328 | M37: 3.43 | N37: 4.5 | O37: =M37+N37 -> 7.93
A38: 10. 시 설 분 담 금 | H38: =공종별총괄표!L28 -> 0 | K38: 이동형렌탈 | L38: 1625000
A39: 조 사 금 액 | H39: =H36+H37+H38+1 -> 1.995656e+09
A40: 관급자재대(도급자관급) | H40: =공종별총괄표!L12-336 -> 282492000
A41: 관급자재대(관급자관급) | H41: =공종별총괄표!L18-759 -> 176354000
...

Sheet 원가계산서(토목)
A1: 공 사 원 가 계 산 서
A2: =원가제비율!D3 -> 대화면도시재생사업청학당조성공사기본및실시설 | G2: 공사기간 : | H2: =원가제비율!D5 -> 7~12개월이하, 2025.04.01 제비율
A3: 구 분 | E3: 산 출 방 법 | H3: 금 액 | I3: 비 고
A5: 1. 순공사 원가 | E5: [가+나+다] | H5: =H6+H8+H11 -> 57528998
B6: 가. 재료비 | H6: =H7 -> 18422520
C7: 가-1. 직접재료비 | H7: =공종별총괄표!F7 -> 18422520
B8: 나. 노무비 | H8: =H9+H10 -> 12052357
C9: 나-1. 직접노무비 | H9: =공종별총괄표!H7 -> 10489432
C10: 나-2. 간접노무비 | E10: [나1] 의 | G10: =원가제비율!G16 -> 0.149 | H10: =H9*G10 -> 1562925.4
B11: 다. 경비 | H11: =H12+H13+H14+H15+H16+H17+H18+H19+H23+H24+H25+H26+H27+H28+H29 -> 27054120
C12: 다-1. 산출경비 | H12: =공종별총괄표!J7 -> 10255934
C13: 다-2. 산재보험료 | E13: [나] 의 | G13: =원가제비율!G19 -> 0.0356 | H13: =H8*G13 -> 429063.92
C14: 다-3. 고용보험료 | E14: [나] 의 | G14: =원가제비율!G20 -> 0.0101 | H14: =H8*G14 -> 121728.81
C15: 다-4. 국민건강보험료 | E15: [나1] 의 | G15: =원가제비율!G21 -> 0.03545 | H15: =H9*G15 -> 371850.36
C16: 다-5. 노인장기요양보험료 | E16: [다4] 의 | G16: =원가제비율!G22 -> 0.1295 | H16: =INT(H15*G16) -> 48154
C17: 다-6. 국민연금보험료 | E17: [나1] 의 | G17: =원가제비율!G23 -> 0.045 | H17: =H9*G17 -> 472024.44
C18: 다-7. 퇴직공제부금비 | E18: [나1] 의 | G18: =원가제비율!G24 -> 0.023 | H18: =H9*G18 -> 241256.94
C19: 다-8. 산업안전보건관리비 | E19: ※ 관급포함시 : ⓑ와ⓒ 비교후 적은금액 적용 | H19: =H22 -> 886321.96 | K19: 건축분야총괄에 따름
D20: ⓐ.일반의경우 | E20: [가+나1] 의 | F20: =원가제비율!F26 -> 0.0228 | H20: =(H7+H9)*F20+G20 -> 659192.51
D21: ⓑ.ⓐ의 1.2배 | H21: =H20*1.2 -> 791031.01
D22: ⓒ.관급자재대 포함 | E22: [가+나1+관급자재대] 의 | F22: =원가제비율!F28 -> 0.0228 | H22: =(H6+H9+H40/1.1)*F22+G22 -> 886321.96
C23: 다-9. 기타경비 | E23: [가+나] 의 | G23: =원가제비율!G29 -> 0.048 | H23: =(H6+H8)*G23 -> 1462794.1
C24: 다-10. 공사이행보증서 발급수수료 | E24: ([가+나1+다1] 의-140억원*0.019%)*공기(년)
C25: 다-11. 하도급 대금 지급보증서 발급수수료 | E25: [가+나1+다1] 의 | G25: =원가제비율!G31 -> 0.00081 | H25: =(H6+H9+H12)*G25 -> 31725.988
C26: 다-12. 건설기계대여대금지급보증서발급금액 | E26: [가+나1+다1] 의 | G26: =원가제비율!G32 -> 0.0007 | H26: =(H6+H9+H12)*G26 -> 27417.52
C27: 다-13. 환경보전비 | E27: [가+나1+다1] 의 | G27: =원가제비율!G33 -> 0.005 | H27: =(H6+H9+H12)*G27 -> 195839.43
C28: 다-14. 품질관리비
C29: 다-15. 안전관리비 | H29: 12510009
A30: 2. 일 반 관 리 비 | E30: [1] 의 | G30: =원가제비율!G36 -> 0.06 | H30: =H5*G30 -> 3451739.9
A31: 3. 이 윤 | E31: [나+다+2]의 | G31: =원가제비율!G37 -> 0.15 | H31: =(H8+H11+H30)*G31-917/1.1 -> 6382899
A32: 4. T. A. B 공 사
A33: 5. 시공 상세도 작성비
A34: 6. 공 급 가 액 | E34: [1+2+3+4+5] | H34: =(H5+H30+H31+H32+H33) -> 67363637
A35: 7. 부 가 가 치 세 | E35: [6]의 | G35: 0.1 | H35: =H34*G35 -> 6736363.7
A36: 8. 도 급 액 | E36: [6+7] | H36: =H34+H35 -> 74100000
A37: 9. 건설 폐기물 처리비 | H37: =공종별총괄표!L25 -> 955000 | I37: 부가가치세포함
A38: 10. 시 설 분 담 금 | H38: =공종별총괄표!L28 -> 0
A39: 조 사 금 액 | H39: =H36+H37+H38 -> 75055000
A40: 관급자재대(도급자관급) | H40: =공종별총괄표!L13 -> 10958000
A41: 관급자재대(관급자관급) | H41: =공종별총괄표!L19 -> 0
...

Sheet 원가계산서(조경)
A1: 공 사 원 가 계 산 서
A2: =원가제비율!D3 -> 대화면도시재생사업청학당조성공사기본및실시설 | G2: 공사기간 : | H2: =원가제비율!D5 -> 7~12개월이하, 2025.04.01 제비율
A3: 구 분 | E3: 산 출 방 법 | H3: 금 액 | I3: 비 고
A5: 1. 순공사 원가 | E5: [가+나+다] | H5: =H6+H8+H11 -> 0
B6: 가. 재료비 | H6: =H7 -> 0
C7: 가-1. 직접재료비 | H7: =공종별총괄표!F8 -> 0
B8: 나. 노무비 | H8: =H9+H10 -> 0
C9: 나-1. 직접노무비 | H9: =공종별총괄표!H8 -> 0
C10: 나-2. 간접노무비 | E10: [나1] 의 | G10: =원가제비율!G16 -> 0.149 | H10: =H9*G10 -> 0
B11: 다. 경비 | H11: =H12+H13+H14+H15+H16+H17+H18+H19+H23+H24+H25+H26+H27 -> 0
C12: 다-1. 산출경비 | H12: =공종별총괄표!J8 -> 0
C13: 다-2. 산재보험료 | E13: [나] 의 | G13: =원가제비율!G19 -> 0.0356 | H13: =H8*G13 -> 0
C14: 다-3. 고용보험료 | E14: [나] 의 | G14: =원가제비율!G20 -> 0.0101 | H14: =H8*G14 -> 0
C15: 다-4. 국민건강보험료 | E15: [나1] 의 | G15: =원가제비율!G21 -> 0.03545 | H15: =H9*G15 -> 0
C16: 다-5. 노인장기요양보험료 | E16: [다4] 의 | G16: =원가제비율!G22 -> 0.1295 | H16: =INT(H15*G16) -> 0
C17: 다-6. 국민연금보험료 | E17: [나1] 의 | G17: =원가제비율!G23 -> 0.045 | H17: =H9*G17 -> 0
C18: 다-7. 퇴직공제부금비 | E18: [나1] 의 | G18: =원가제비율!G24 -> 0.023 | H18: =H9*G18 -> 0
C19: 다-8. 산업안전보건관리비 | E19: ※ 관급포함시 : ⓑ와ⓒ 비교후 적은금액 적용 | H19: =H22 -> 0 | K19: 건축분야총괄에 따름
D20: ⓐ.일반의경우 | E20: [가+나1] 의 | F20: =원가제비율!F26 -> 0.0228 | H20: =(H7+H9)*F20+G20 -> 0
D21: ⓑ.ⓐ의 1.2배 | H21: =H20*1.2 -> 0
D22: ⓒ.관급자재대 포함 | E22: [가+나1+관급자재대] 의 | F22: =원가제비율!F28 -> 0.0228 | H22: =(H6+H9+H39/1.1)*F22+G22 -> 0
C23: 다-9. 기타경비 | E23: [가+나] 의 | G23: =원가제비율!G29 -> 0.048 | H23: =(H6+H8)*G23 -> 0
C24: 다-10. 공사이행보증서 발급수수료 | E24: ([가+나1+다1] 의-140억원*0.019%)*공기(년)
C25: 다-11. 하도급 대금 지급보증서 발급수수료 | E25: [가+나1+다1] 의 | G25: =원가제비율!G31 -> 0.00081 | H25: =(H6+H9+H12)*G25 -> 0
C26: 다-12. 건설기계대여대금지급보증서발급금액 | E26: [가+나1+다1] 의 | G26: =원가제비율!G32 -> 0.0007 | H26: =(H6+H9+H12)*G26 -> 0
C27: 다-13. 환경보전비 | E27: [가+나1+다1] 의 | G27: =원가제비율!G33 -> 0.005 | H27: =(H6+H9+H12)*G27 -> 0
C28: 다-14. 품질관리비
C29: 다-15. 안전관리비
A30: 2. 일 반 관 리 비 | E30: [1] 의 | G30: =원가제비율!G36 -> 0.06 | H30: =H5*G30 -> 0
A31: 3. 이 윤 | E31: [나+다+2]의 | G31: =원가제비율!G37 -> 0.15 | H31: =(H8+H11+H30)*G31 -> 0
A32: 4. T. A. B 공 사
A33: 5. 총 원 가 | E33: [1+2+3+4] | H33: =(H5+H30+H31+H32) -> 0
A34: 6. 부 가 가 치 세 | E34: [5]의 | G34: 0.1 | H34: =H33*G34 -> 0
A35: 7. 총 계 | E35: [5+6] | H35: =H33+H34 -> 0
A36: 8. 건설 폐기물 처리비
A37: 9. 시 설 분 담 금 | H37: =공종별총괄표!L28 -> 0
A38: 조 사 금 액 | H38: =H35+H36+H37 -> 0
A39: 관급자재대(도급자관급) | H39: =공종별총괄표!L14 -> 0
A40: 관급자재대(관급자관급) | H40: =공종별총괄표!L20 -> 0
A41: 총 공 사 비 | H41: =H38+H39+H40 -> 0

Sheet 원가계산서(기계)
A1: 공 사 원 가 계 산 서
A2: =원가제비율!D3 -> 대화면도시재생사업청학당조성공사기본및실시설 | G2: 공사기간 : | H2: =원가제비율!D5 -> 7~12개월이하, 2025.04.01 제비율
A3: 구 분 | E3: 산 출 방 법 | H3: 금 액 | I3: 비 고
A5: 1. 순공사 원가 | E5: [가+나+다] | H5: =H6+H8+H11 -> 78906950
B6: 가. 재료비 | H6: =H7 -> 50295405
C7: 가-1. 직접재료비 | H7: =공종별총괄표!F9 -> 50295405
B8: 나. 노무비 | H8: =H9+H10 -> 20334804
C9: 나-1. 직접노무비 | H9: =공종별총괄표!H9 -> 17697828
C10: 나-2. 간접노무비 | E10: [나1] 의 | G10: =원가제비율!G16 -> 0.149 | H10: =H9*G10 -> 2636976.4
B11: 다. 경비 | H11: =H12+H13+H14+H15+H16+H17+H18+H19+H23+H24+H25+H26+H27+H28+H29 -> 8276740.3
C12: 다-1. 산출경비 | H12: =공종별총괄표!J9 -> 51884
C13: 다-2. 산재보험료 | E13: [나] 의 | G13: =원가제비율!G19 -> 0.0356 | H13: =H8*G13 -> 723919.04
C14: 다-3. 고용보험료 | E14: [나] 의 | G14: =원가제비율!G20 -> 0.0101 | H14: =H8*G14 -> 205381.52
C15: 다-4. 국민건강보험료 | E15: [나1] 의 | G15: =원가제비율!G21 -> 0.03545 | H15: =H9*G15 -> 627388
C16: 다-5. 노인장기요양보험료 | E16: [다4] 의 | G16: =원가제비율!G22 -> 0.1295 | H16: =INT(H15*G16) -> 81246
C17: 다-6. 국민연금보험료 | E17: [나1] 의 | G17: =원가제비율!G23 -> 0.045 | H17: =H9*G17 -> 796402.26
C18: 다-7. 퇴직공제부금비 | E18: [나1] 의 | G18: =원가제비율!G24 -> 0.023 | H18: =H9*G18 -> 407050.04
C19: 다-8. 산업안전보건관리비 | E19: ※ 관급포함시 : ⓑ와ⓒ 비교후 적은금액 적용 | H19: =H22 -> 1550245.7 | K19: 건축분야총괄에 따름
D20: ⓐ.일반의경우 | E20: [가+나1] 의 | F20: =원가제비율!F26 -> 0.0228 | H20: =(H7+H9)*F20+G20 -> 1550245.7
D21: ⓑ.ⓐ의 1.2배 | H21: =H20*1.2 -> 1860294.9
D22: ⓒ.관급자재대 포함 | E22: [가+나1+관급자재대] 의 | F22: =원가제비율!F28 -> 0.0228 | H22: =(H6+H9+H40/1.1)*F22+G22 -> 1550245.7
C23: 다-9. 기타경비 | E23: [가+나] 의 | G23: =원가제비율!G29 -> 0.048 | H23: =(H6+H8)*G23 -> 3390250
C24: 다-10. 공사이행보증서 발급수수료 | E24: ([가+나1+다1] 의-140억원*0.019%)*공기(년)
C25: 다-11. 하도급 대금 지급보증서 발급수수료 | E25: [가+나1+다1] 의 | G25: =원가제비율!G31 -> 0.00081 | H25: =(H6+H9+H12)*G25 -> 55116.545
C26: 다-12. 건설기계대여대금지급보증서발급금액 | E26: [가+나1+다1] 의 | G26: =원가제비율!G32 -> 0.0007 | H26: =(H6+H9+H12)*G26 -> 47631.582
C27: 다-13. 환경보전비 | E27: [가+나1+다1] 의 | G27: =원가제비율!G33 -> 0.005 | H27: =(H6+H9+H12)*G27 -> 340225.59
C28: 다-14. 품질관리비
C29: 다-15. 안전관리비
A30: 2. 일 반 관 리 비 | E30: [1] 의 | G30: =원가제비율!G36 -> 0.06 | H30: =H5*G30 -> 4734417
A31: 3. 이 윤 | E31: [나+다+2]의 | G31: =원가제비율!G37 -> 0.15 | H31: =(H8+H11+H30)*G31-587/1.1 -> 5001360.6
A32: 4. T. A. B 공 사
A33: 5. 시공 상세도 작성비
A34: 6. 공 급 가 액 | E34: [1+2+3+4+5] | H34: =(H5+H30+H31+H32+H33) -> 88642727
A35: 7. 부 가 가 치 세 | E35: [6]의 | G35: 0.1 | H35: =H34*G35 -> 8864272.7
A36: 8. 도 급 액 | E36: [6+7] | H36: =H34+H35 -> 97507000
A37: 9. 건설 폐기물 처리비
A38: 10. 시 설 분 담 금 | H38: =공종별총괄표!L28 -> 0
A39: 조 사 금 액 | H39: =H36+H37+H38 -> 97507000
A40: 관급자재대(도급자관급) | H40: =공종별총괄표!L15 -> 0
A41: 관급자재대(관급자관급) | H41: =공종별총괄표!L21-580 -> 42930000
...

Sheet 원가계산서(폐기물)
A1: 공 사 원 가 계 산 서
A2: =원가제비율!D3 -> 대화면도시재생사업청학당조성공사기본및실시설 | G2: 공사기간 : | H2: =원가제비율!D5 -> 7~12개월이하, 2025.04.01 제비율
A3: 구 분 | E3: 산 출 방 법 | H3: 금 액 | I3: 비 고
A5: 1. 순공사 원가 | E5: [가+나+다] | H5: =H6+H8+H11 -> 0
B6: 가. 재료비 | H6: =H7 -> 0
C7: 가-1. 직접재료비
B8: 나. 노무비 | H8: =H9+H10 -> 0
C9: 나-1. 직접노무비
C10: 나-2. 간접노무비 | E10: [나1] 의 | G10: =원가제비율!G16 -> 0.149 | H10: =H9*G10 -> 0
B11: 다. 경비 | H11: =H12+H13+H14+H15+H16+H17+H18+H19+H23+H24+H25+H26+H27+H28+H29 -> 0
C12: 다-1. 산출경비
C13: 다-2. 산재보험료 | E13: [나] 의 | G13: =원가제비율!G19 -> 0.0356 | H13: =H8*G13 -> 0
C14: 다-3. 고용보험료 | E14: [나] 의 | G14: =원가제비율!G20 -> 0.0101 | H14: =H8*G14 -> 0
C15: 다-4. 국민건강보험료 | E15: [나1] 의 | G15: =원가제비율!G21 -> 0.03545 | H15: =H9*G15 -> 0
C16: 다-5. 노인장기요양보험료 | E16: [다4] 의 | G16: =원가제비율!G22 -> 0.1295 | H16: =INT(H15*G16) -> 0
C17: 다-6. 국민연금보험료 | E17: [나1] 의 | G17: =원가제비율!G23 -> 0.045 | H17: =H9*G17 -> 0
C18: 다-7. 퇴직공제부금비 | E18: [나1] 의 | G18: =원가제비율!G24 -> 0.023 | H18: =H9*G18 -> 0
C19: 다-8. 산업안전보건관리비 | E19: ※ 관급포함시 : ⓑ와ⓒ 비교후 적은금액 적용
D20: ⓐ.일반의경우 | E20: [가+나1] 의 | F20: =원가제비율!F26 -> 0.0228
D21: ⓑ.ⓐ의 1.2배 | H21: =H20*1.2 -> 0
D22: ⓒ.관급자재대 포함 | E22: [가+나1+관급자재대] 의 | F22: =원가제비율!F28 -> 0.0228
C23: 다-9. 기타경비 | E23: [가+나] 의 | G23: =원가제비율!G29 -> 0.048 | H23: =(H6+H8)*G23 -> 0
C24: 다-10. 공사이행보증서 발급수수료 | E24: ([가+나1+다1] 의-140억원*0.019%)*공기(년)
C25: 다-11. 하도급 대금 지급보증서 발급수수료 | E25: [가+나1+다1] 의 | G25: =원가제비율!G31 -> 0.00081 | H25: =(H6+H9+H12)*G25 -> 0
C26: 다-12. 건설기계대여대금지급보증서발급금액 | E26: [가+나1+다1] 의 | G26: =원가제비율!G32 -> 0.0007 | H26: =(H6+H9+H12)*G26 -> 0
C27: 다-13. 환경보전비 | E27: [가+나1+다1] 의 | G27: =원가제비율!G33 -> 0.005 | H27: =(H6+H9+H12)*G27 -> 0
C28: 다-14. 품질관리비
C29: 다-15. 안전관리비
A30: 2. 일 반 관 리 비 | E30: [1] 의 | G30: =원가제비율!G36 -> 0.06 | H30: =H5*G30 -> 0
A31: 3. 이 윤 | E31: [나+다+2]의 | G31: =원가제비율!G37 -> 0.15 | H31: =(H8+H11+H30)*G31 -> 0
A32: 4. 총 원 가 | E32: [1+2+3+4]
A33: 5. 부 가 가 치 세 | E33: [5]의 | G33: 0.1 | H33: =H32*G33 -> 0
A34: 6. 총 계 | E34: [5+6] | H34: =H32+H33 -> 0
A35: 조 사 금 액 | H35: =H34 -> 0
A36: 관급자재대(도급자관급)
A37: 관급자재대(관급자관급)
A38: 총 공 사 비 | H38: =H35+H36+H37 -> 0

Sheet 공종별총괄표
A1: 공 종 별 총 괄 집 계 표
A2: =원가제비율!D3 -> 대화면도시재생사업청학당조성공사기본및실시설
A3: 품 명 | B3: 규 격 | C3: 단위 | D3: 수량 | E3: 재 료 비 | G3: 노 무 비 | I3: 경 비 | K3: 합 계 | M3: 비 고 | N3: 공종코드 | O3: 변수 | P3: 상위공종 | Q3: 공종구분 | R3: 공종레벨 | S3: 공종소계 | T3: 원가계산서 연결금액
E4: 단 가 | F4: 금 액 | G4: 단 가 | H4: 금 액 | I4: 단 가 | J4: 금 액 | K4: 단 가 | L4: 금 액
A5: =원가제비율!D3 -> 대화면도시재생사업청학당조성공사기본및실시설 | D5: 1 | E5: =F6+F7+F8+F9 -> 560141843 | F5: =E5*D5 -> 560141843 | G5: =H6+H7+H8+H9 -> 663662901 | H5: =G5*D5 -> 663662901 | I5: =J6+J7+J8+J9 -> 113799309 | J5: =I5*D5 -> 113799309 | K5: =E5+G5+I5 -> 1337604053 | L5: =F5+H5+J5 -> 1337604053 | N5: 01 | R5: 1
A6: 01 건축공사 | B6: 건축 | D6: 1 | E6: =공종별집계표!F6 -> 491423918 | F6: =E6*D6 -> 491423918 | G6: =공종별집계표!H6 -> 635475641 | H6: =G6*D6 -> 635475641 | I6: =공종별집계표!J6 -> 103491491 | J6: =I6*D6 -> 103491491 | K6: =E6+G6+I6 -> 1230391050 | L6: =F6+H6+J6 -> 1230391050 | N6: 0101 | P6: 01 | R6: 2
A7: 02 토목공사 | B7: 토목 | D7: 1 | E7: 18422520 | F7: =E7*D7 -> 18422520 | G7: 10489432 | H7: =G7*D7 -> 10489432 | I7: 10255934 | J7: =I7*D7 -> 10255934 | K7: =E7+G7+I7 -> 39167886 | L7: =F7+H7+J7 -> 39167886 | N7: 010103 | P7: 0101 | R7: 3
A8: 03 조경공사 | B8: 조경 | D8: 1 | F8: =E8*D8 -> 0 | H8: =G8*D8 -> 0 | J8: =I8*D8 -> 0 | K8: =E8+G8+I8 -> 0 | L8: =F8+H8+J8 -> 0 | N8: 010103 | P8: 0101 | R8: 3
A9: 03 기계공사 | B9: 기계 | D9: 1 | E9: 50295405 | F9: =E9*D9 -> 50295405 | G9: 17697828 | H9: =G9*D9 -> 17697828 | I9: 51884 | J9: =I9*D9 -> 51884 | K9: =E9+G9+I9 -> 68045117 | L9: =F9+H9+J9 -> 68045117
A11: < 도급자(시공업체)설치 관급자재 내역 > | D11: 1 | E11: =F12+F13+F14+F15 -> 291874071 | F11: =E11*D11 -> 291874071 | G11: =H12+H13+H14+H15 -> 0 | H11: =G11*D11 -> 0 | I11: =J12+J13+J14+J15 -> 1576265 | J11: =I11*D11 -> 1576265 | K11: =L12+L13+L14+L15 -> 293450336 | L11: =F11+H11+J11 -> 293450336
A12: 01 관급재비 | B12: 건축 | D12: 1 | E12: =공종별집계표!F38 -> 280975071 | F12: =E12*D12 -> 280975071 | G12: =공종별집계표!H38 -> 0 | H12: =G12*D12 -> 0 | I12: =공종별집계표!J38 -> 1517265 | J12: =I12*D12 -> 1517265 | K12: =E12+G12+I12 -> 282492336 | L12: =F12+H12+J12 -> 282492336
A13: 02.관급재비 | B13: 토목 | D13: 1 | E13: 10899000 | F13: =E13*D13 -> 10899000 | H13: =G13*D13 -> 0 | I13: 59000 | J13: =I13*D13 -> 59000 | K13: =E13+G13+I13 -> 10958000 | L13: =F13+H13+J13 -> 10958000
A14: 03.관급재비 | B14: 조경 | D14: 1 | F14: =E14*D14 -> 0 | H14: =G14*D14 -> 0 | J14: =I14*D14 -> 0 | K14: =E14+G14+I14 -> 0 | L14: =F14+H14+J14 -> 0
A15: 03.관급재비 | B15: 기계 | D15: 1 | F15: =E15*D15 -> 0 | H15: =G15*D15 -> 0 | J15: =I15*D15 -> 0 | K15: =E15+G15+I15 -> 0 | L15: =F15+H15+J15 -> 0
A17: < 관급자(제조업체)설치 관급자재 내역 > | D17: 1 | E17: =F18+F19+F20+F21 -> 218612260 | F17: =E17*D17 -> 218612260 | G17: =H18+H19+H20+H21 -> 0 | H17: =G17*D17 -> 0 | I17: =J18+J19+J20+J21 -> 673079 | J17: =I17*D17 -> 673079 | K17: =L18+L19+L20+L21 -> 219285339 | L17: =F17+H17+J17 -> 219285339
A18: 01 관급재비 | B18: 건축 | D18: 1 | E18: =공종별집계표!F39 -> 175681680 | F18: =E18*D18 -> 175681680 | G18: =공종별집계표!H39 -> 0 | H18: =G18*D18 -> 0 | I18: =공종별집계표!J39 -> 673079 | J18: =I18*D18 -> 673079 | K18: =E18+G18+I18 -> 176354759 | L18: =F18+H18+J18 -> 176354759
A19: 02.관급재비 | B19: 토목 | D19: 1 | F19: =E19*D19 -> 0 | H19: =G19*D19 -> 0 | J19: =I19*D19 -> 0 | K19: =E19+G19+I19 -> 0 | L19: =F19+H19+J19 -> 0
A20: 03.관급재비 | B20: 조경 | D20: 1 | F20: =E20*D20 -> 0 | H20: =G20*D20 -> 0 | J20: =I20*D20 -> 0 | K20: =E20+G20+I20 -> 0 | L20: =F20+H20+J20 -> 0
A21: =A15 -> 03.관급재비 | B21: 기계 | D21: 1 | E21: 42930580 | F21: =E21*D21 -> 42930580 | H21: =G21*D21 -> 0 | J21: =I21*D21 -> 0 | K21: =E21+G21+I21 -> 42930580 | L21: =F21+H21+J21 -> 42930580
A23: < 건설폐기물처리비 > | D23: 1 | E23: =F24+F25 -> 0 | F23: =E23*D23 -> 0 | G23: =H24+H25 -> 0 | H23: =G23*D23 -> 0 | I23: =J24+J25 -> 3815517 | J23: =I23*D23 -> 3815517 | K23: =L24+L25 -> 3815517 | L23: =F23+H23+J23 -> 3815517
A24: 01.건설폐기물처리비 | B24: 건축 | D24: 1 | F24: =E24*D24 -> 0 | H24: =G24*D24 -> 0 | I24: =공종별집계표!L32 -> 2860517 | J24: =I24*D24 -> 2860517 | K24: =E24+G24+I24 -> 2860517 | L24: =F24+H24+J24 -> 2860517 | M24: 부가가치세 미포함
A25: 02.건설폐기물처리비 | B25: 토목 | D25: 1 | F25: =E25*D25 -> 0 | H25: =G25*D25 -> 0 | I25: 955000 | J25: =I25*D25 -> 955000 | K25: =E25+G25+I25 -> 955000 | L25: =F25+H25+J25 -> 955000 | M25: 부가가치세 미포함
A27: < 기타경비 > | D27: 1 | E27: =F28 -> 0 | F27: =E27*D27 -> 0 | G27: =H28 -> 0 | H27: =G27*D27 -> 0 | I27: =J28 -> 0 | J27: =I27*D27 -> 0 | K27: =L28 -> 0 | L27: =F27+H27+J27 -> 0
A28: 01.시설분담금 | B28: 기계 | D28: 1 | F28: =E28*D28 -> 0 | H28: =G28*D28 -> 0 | J28: =I28*D28 -> 0 | K28: =E28+G28+I28 -> 0 | L28: =F28+H28+J28 -> 0
A29: [ 합 계 ] | F29: =F5 -> 560141843 | H29: =H5 -> 663662901 | J29: =J5 -> 113799309 | L29: =L5 -> 1337604053

Sheet 공종별집계표
A1: 공 종 별 집 계 표
A2: [ 대화면도시재생사업청학당조성공사기본및실시설 ]
A3: 품 명 | B3: 규 격 | C3: 단위 | D3: 수량 | E3: 재 료 비 | G3: 노 무 비 | I3: 경 비 | K3: 합 계 | M3: 비 고 | N3: 공종코드 | O3: 변수 | P3: 상위공종 | Q3: 공종구분 | R3: 공종레벨 | S3: 공종소계 | T3: 원가계산서 연결금액
E4: 단 가 | F4: 금 액 | G4: 단 가 | H4: 금 액 | I4: 단 가 | J4: 금 액 | K4: 단 가 | L4: 금 액
A5: 01 대화면도시재생사업청학당조성공사기본및실시설 | D5: 1 | E5: =F6 -> 491423918 | F5: =E5*D5 -> 491423918 | G5: =H6 -> 635475641 | H5: =G5*D5 -> 635475641 | I5: =J6 -> 103491491 | J5: =I5*D5 -> 103491491 | K5: =E5+G5+I5 -> 1230391050 | L5: =F5+H5+J5 -> 1230391050 | N5: 01 | R5: 1
A6: 0101 ★ 근린생활시설 | D6: 1 | E6: =F7+F8+F9+F10+F11+F12+F13+F14+F15+F16+F17+F18+F19+F20+F21+F22+F23+F24+F25+F26+F27+F28+F29+F30+F31 -> 491423918 | F6: =E6*D6 -> 491423918 | G6: =H7+H8+H9+H10+H11+H12+H13+H14+H15+H16+H17+H18+H19+H20+H21+H22+H23+H24+H25+H26+H27+H28+H29+H30+H31 -> 635475641 | H6: =G6*D6 -> 635475641 | I6: =J7+J8+J9+J10+J11+J12+J13+J14+J15+J16+J17+J18+J19+J20+J21+J22+J23+J24+J25+J26+J27+J28+J29+J30+J31 -> 103491491 | J6: =I6*D6 -> 103491491 | K6: =E6+G6+I6 -> 1230391050 | L6: =F6+H6+J6 -> 1230391050 | N6: 0101 | P6: 01 | R6: 2
A7: 010101 공통 가설 공사 | D7: 1 | E7: =공종별내역서!F28 -> 0 | F7: =E7*D7 -> 0 | G7: =공종별내역서!H28 -> 0 | H7: =G7*D7 -> 0 | I7: =공종별내역서!J28 -> 20653465 | J7: =I7*D7 -> 20653465 | K7: =E7+G7+I7 -> 20653465 | L7: =F7+H7+J7 -> 20653465 | N7: 010101 | P7: 0101 | R7: 3
A8: 010102 가 설 공 사 | D8: 1 | E8: =공종별내역서!F54 -> 9123799 | F8: =E8*D8 -> 9123799 | G8: =공종별내역서!H54 -> 51271240 | H8: =G8*D8 -> 51271240 | I8: =공종별내역서!J54 -> 110504 | J8: =I8*D8 -> 110504 | K8: =E8+G8+I8 -> 60505543 | L8: =F8+H8+J8 -> 60505543 | N8: 010102 | P8: 0101 | R8: 3
A9: 010103 토 및 지정공사 | D9: 1 | E9: =공종별내역서!F80 -> 56819539 | F9: =E9*D9 -> 56819539 | G9: =공종별내역서!H80 -> 35369090 | H9: =G9*D9 -> 35369090 | I9: =공종별내역서!J80 -> 25904410 | J9: =I9*D9 -> 25904410 | K9: =E9+G9+I9 -> 118093039 | L9: =F9+H9+J9 -> 118093039 | N9: 010103 | P9: 0101 | R9: 3
A10: 010104 철근콘크리트공사 | D10: 1 | E10: =공종별내역서!F106 -> 13080821 | F10: =E10*D10 -> 13080821 | G10: =공종별내역서!H106 -> 105695233 | H10: =G10*D10 -> 105695233 | I10: =공종별내역서!J106 -> 9330457 | J10: =I10*D10 -> 9330457 | K10: =E10+G10+I10 -> 128106511 | L10: =F10+H10+J10 -> 128106511 | N10: 010104 | P10: 0101 | R10: 3
A11: 010105 철 골 공 사 | D11: 1 | E11: =공종별내역서!F158 -> 66944921 | F11: =E11*D11 -> 66944921 | G11: =공종별내역서!H158 -> 108100919 | H11: =G11*D11 -> 108100919 | I11: =공종별내역서!J158 -> 32350062 | J11: =I11*D11 -> 32350062 | K11: =E11+G11+I11 -> 207395902 | L11: =F11+H11+J11 -> 207395902 | N11: 010105 | P11: 0101 | R11: 3
A12: 010106 조 적 공 사 | D12: 1 | E12: =공종별내역서!F184 -> 1059015 | F12: =E12*D12 -> 1059015 | G12: =공종별내역서!H184 -> 7406743 | H12: =G12*D12 -> 7406743 | I12: =공종별내역서!J184 -> 122450 | J12: =I12*D12 -> 122450 | K12: =E12+G12+I12 -> 8588208 | L12: =F12+H12+J12 -> 8588208 | N12: 010106 | P12: 0101 | R12: 3
A13: 010107 돌 공 사 | D13: 1 | E13: =공종별내역서!F210 -> 588627 | F13: =E13*D13 -> 588627 | G13: =공종별내역서!H210 -> 157028 | H13: =G13*D13 -> 157028 | I13: =공종별내역서!J210 -> 1516 | J13: =I13*D13 -> 1516 | K13: =E13+G13+I13 -> 747171 | L13: =F13+H13+J13 -> 747171 | N13: 010107 | P13: 0101 | R13: 3
A14: 010108 타 일 공 사 | D14: 1 | E14: =공종별내역서!F236 -> 1770999 | F14: =E14*D14 -> 1770999 | G14: =공종별내역서!H236 -> 7195728 | H14: =G14*D14 -> 7195728 | I14: =공종별내역서!J236 -> 172577 | J14: =I14*D14 -> 172577 | K14: =E14+G14+I14 -> 9139304 | L14: =F14+H14+J14 -> 9139304 | N14: 010108 | P14: 0101 | R14: 3
A15: 010109 방 수 공 사 | D15: 1 | E15: =공종별내역서!F262 -> 23743969 | F15: =E15*D15 -> 23743969 | G15: =공종별내역서!H262 -> 40563363 | H15: =G15*D15 -> 40563363 | I15: =공종별내역서!J262 -> 35650 | J15: =I15*D15 -> 35650 | K15: =E15+G15+I15 -> 64342982 | L15: =F15+H15+J15 -> 64342982 | N15: 010109 | P15: 0101 | R15: 3
A16: 010110 지붕 및 홈통공사 | D16: 1 | E16: =공종별내역서!F288 -> 5751711 | F16: =E16*D16 -> 5751711 | G16: =공종별내역서!H288 -> 4704180 | H16: =G16*D16 -> 4704180 | I16: =공종별내역서!J288 -> 63564 | J16: =I16*D16 -> 63564 | K16: =E16+G16+I16 -> 10519455 | L16: =F16+H16+J16 -> 10519455 | N16: 010110 | P16: 0101 | R16: 3
A17: 010111 금 속 공 사 | D17: 1 | E17: =공종별내역서!F340 -> 54539263 | F17: =E17*D17 -> 54539263 | G17: =공종별내역서!H340 -> 22234682 | H17: =G17*D17 -> 22234682 | I17: =공종별내역서!J340 -> 878190 | J17: =I17*D17 -> 878190 | K17: =E17+G17+I17 -> 77652135 | L17: =F17+H17+J17 -> 77652135 | N17: 010111 | P17: 0101 | R17: 3
A18: 010112 미 장 공 사 | D18: 1 | E18: =공종별내역서!F366 -> 2297790 | F18: =E18*D18 -> 2297790 | G18: =공종별내역서!H366 -> 22120593 | H18: =G18*D18 -> 22120593 | I18: =공종별내역서!J366 -> 408875 | J18: =I18*D18 -> 408875 | K18: =E18+G18+I18 -> 24827258 | L18: =F18+H18+J18 -> 24827258 | N18: 010112 | P18: 0101 | R18: 3
A19: 010113 창 호 공 사 | D19: 1 | E19: =공종별내역서!F418 -> 24506123 | F19: =E19*D19 -> 24506123 | G19: =공종별내역서!H418 -> 9425049 | H19: =G19*D19 -> 9425049 | I19: =공종별내역서!J418 -> 309304 | J19: =I19*D19 -> 309304 | K19: =E19+G19+I19 -> 34240476 | L19: =F19+H19+J19 -> 34240476 | N19: 010113 | P19: 0101 | R19: 3
A20: 010114 유 리 공 사 | D20: 1 | E20: =공종별내역서!F444 -> 23889640 | F20: =E20*D20 -> 23889640 | G20: =공종별내역서!H444 -> 10852500 | H20: =G20*D20 -> 10852500 | I20: =공종별내역서!J444 -> 1488 | J20: =I20*D20 -> 1488 | K20: =E20+G20+I20 -> 34743628 | L20: =F20+H20+J20 -> 34743628 | N20: 010114 | P20: 0101 | R20: 3
A21: 010115 칠 공 사 | D21: 1 | E21: =공종별내역서!F470 -> 13879267 | F21: =E21*D21 -> 13879267 | G21: =공종별내역서!H470 -> 34960448 | H21: =G21*D21 -> 34960448 | I21: =공종별내역서!J470 -> 0 | J21: =I21*D21 -> 0 | K21: =E21+G21+I21 -> 48839715 | L21: =F21+H21+J21 -> 48839715 | N21: 010115 | P21: 0101 | R21: 3
A22: 010116 수 장 공 사 | D22: 1 | E22: =공종별내역서!F496 -> 166411764 | F22: =E22*D22 -> 166411764 | G22: =공종별내역서!H496 -> 103682382 | H22: =G22*D22 -> 103682382 | I22: =공종별내역서!J496 -> 1769937 | J22: =I22*D22 -> 1769937 | K22: =E22+G22+I22 -> 271864083 | L22: =F22+H22+J22 -> 271864083 | N22: 010116 | P22: 0101 | R22: 3
A23: 010117 기 타 공 사 | D23: 1 | E23: =공종별내역서!F522 -> 579250 | F23: =E23*D23 -> 579250 | G23: =공종별내역서!H522 -> 203980 | H23: =G23*D23 -> 203980 | I23: =공종별내역서!J522 -> 4350 | J23: =I23*D23 -> 4350 | K23: =E23+G23+I23 -> 787580 | L23: =F23+H23+J23 -> 787580 | N23: 010117 | P23: 0101 | R23: 3
A24: 010118 판 넬 공 사 | D24: 1 | E24: =공종별내역서!F548 -> 6133900 | F24: =E24*D24 -> 6133900 | G24: =공종별내역서!H548 -> 58403079 | H24: =G24*D24 -> 58403079 | I24: =공종별내역서!J548 -> 2734117 | J24: =I24*D24 -> 2734117 | K24: =E24+G24+I24 -> 67271096 | L24: =F24+H24+J24 -> 67271096 | N24: 010118 | P24: 0101 | R24: 3
A25: 010119 부 대 공 사 | D25: 1 | E25: =공종별내역서!F574 -> 4709351 | F25: =E25*D25 -> 4709351 | G25: =공종별내역서!H574 -> 5514258 | H25: =G25*D25 -> 5514258 | I25: =공종별내역서!J574 -> 433193 | J25: =I25*D25 -> 433193 | K25: =E25+G25+I25 -> 10656802 | L25: =F25+H25+J25 -> 10656802 | N25: 010119 | P25: 0101 | R25: 3
A26: 010120 조 경 공 사 | D26: 1 | E26: =공종별내역서!F600 -> 7642890 | F26: =E26*D26 -> 7642890 | G26: =공종별내역서!H600 -> 4927398 | H26: =G26*D26 -> 4927398 | I26: =공종별내역서!J600 -> 324820 | J26: =I26*D26 -> 324820 | K26: =E26+G26+I26 -> 12895108 | L26: =F26+H26+J26 -> 12895108 | N26: 010120 | P26: 0101 | R26: 3
A27: 010121 철 거 공 사 | D27: 1 | E27: =공종별내역서!F626 -> 3196104 | F27: =E27*D27 -> 3196104 | G27: =공종별내역서!H626 -> 2687748 | H27: =G27*D27 -> 2687748 | I27: =공종별내역서!J626 -> 1074384 | J27: =I27*D27 -> 1074384 | K27: =E27+G27+I27 -> 6958236 | L27: =F27+H27+J27 -> 6958236 | N27: 010121 | P27: 0101 | R27: 3
A28: 010122 관급자재관리비 | D28: 1 | E28: =공종별내역서!F652 -> 0 | F28: =E28*D28 -> 0 | G28: =공종별내역서!H652 -> 0 | H28: =G28*D28 -> 0 | I28: =공종별내역서!J652 -> 153000 | J28: =I28*D28 -> 153000 | K28: =E28+G28+I28 -> 153000 | L28: =F28+H28+J28 -> 153000 | N28: 010122 | P28: 0101 | R28: 3
A29: 010123 골 재 비 | D29: 1 | E29: =공종별내역서!F678 -> 6403250 | F29: =E29*D29 -> 6403250 | G29: =공종별내역서!H678 -> 0 | H29: =G29*D29 -> 0 | I29: =공종별내역서!J678 -> 0 | J29: =I29*D29 -> 0 | K29: =E29+G29+I29 -> 6403250 | L29: =F29+H29+J29 -> 6403250 | N29: 010123 | P29: 0101 | R29: 3
A30: 010124 운 반 비 | D30: 1 | E30: =공종별내역서!F704 -> 0 | F30: =E30*D30 -> 0 | G30: =공종별내역서!H704 -> 0 | H30: =G30*D30 -> 0 | I30: =공종별내역서!J704 -> 6655178 | J30: =I30*D30 -> 6655178 | K30: =E30+G30+I30 -> 6655178 | L30: =F30+H30+J30 -> 6655178 | N30: 010124 | P30: 0101 | R30: 3
A31: 010125 작 업 부 산 물 | D31: 1 | E31: =공종별내역서!F730 -> -1648075 | F31: =E31*D31 -> -1648075 | G31: =공종별내역서!H730 -> 0 | H31: =G31*D31 -> 0 | I31: =공종별내역서!J730 -> 0 | J31: =I31*D31 -> 0 | K31: =E31+G31+I31 -> -1648075 | L31: =F31+H31+J31 -> -1648075 | N31: 010125 | P31: 0101 | R31: 3
A32: 010126 건설폐기물처리비 | D32: 1 | E32: =공종별내역서!F756 -> 0 | F32: =E32*D32 -> 0 | G32: =공종별내역서!H756 -> 0 | H32: =G32*D32 -> 0 | I32: =공종별내역서!J756 -> 2860517 | J32: =I32*D32 -> 2860517 | K32: =E32+G32+I32 -> 2860517 | L32: =F32+H32+J32 -> 2860517 | N32: 010126 | Q32: 8 | R32: 3 | T32: =L32*1 -> 2860517
A33: 0102 ◆ 품질 관리비 | D33: 1 | E33: =F34 -> 0 | F33: =E33*D33 -> 0 | G33: =H34 -> 0 | H33: =G33*D33 -> 0 | I33: =J34 -> 7798410 | J33: =I33*D33 -> 7798410 | K33: =E33+G33+I33 -> 7798410 | L33: =F33+H33+J33 -> 7798410 | N33: 0102 | Q33: 4 | R33: 2 | T33: =L33*1 -> 7798410
A34: 010201 품질 관리비 | D34: 1 | E34: =공종별내역서!F860 -> 0 | F34: =E34*D34 -> 0 | G34: =공종별내역서!H860 -> 0 | H34: =G34*D34 -> 0 | I34: =공종별내역서!J860 -> 7798410 | J34: =I34*D34 -> 7798410 | K34: =E34+G34+I34 -> 7798410 | L34: =F34+H34+J34 -> 7798410 | N34: 010201 | P34: 0102 | R34: 3
A35: 0103 ◆ 안전 관리비 | D35: 1 | E35: =F36 -> 0 | F35: =E35*D35 -> 0 | G35: =H36 -> 0 | H35: =G35*D35 -> 0 | I35: =J36 -> 9000000 | J35: =I35*D35 -> 9000000 | K35: =E35+G35+I35 -> 9000000 | L35: =F35+H35+J35 -> 9000000 | N35: 0103 | Q35: 4 | R35: 2 | T35: =L35*1 -> 9000000
A36: 010301 안전 관리비 | D36: 1 | E36: =공종별내역서!F886 -> 0 | F36: =E36*D36 -> 0 | G36: =공종별내역서!H886 -> 0 | H36: =G36*D36 -> 0 | I36: =공종별내역서!J886 -> 9000000 | J36: =I36*D36 -> 9000000 | K36: =E36+G36+I36 -> 9000000 | L36: =F36+H36+J36 -> 9000000 | N36: 010301 | P36: 0103 | R36: 3
A37: 0104 ★ 관 급 자 재 | D37: 1 | E37: =F38+F39 -> 456656751 | F37: =E37*D37 -> 456656751 | G37: =H38+H39 -> 0 | H37: =G37*D37 -> 0 | I37: =J38+J39 -> 2190344 | J37: =I37*D37 -> 2190344 | K37: =E37+G37+I37 -> 458847095 | L37: =F37+H37+J37 -> 458847095 | N37: 0104 | Q37: 7 | R37: 2 | T37: =L37*1 -> 458847095
A38: 010401 관급자재[도급자] | D38: 1 | E38: =공종별내역서!F938 -> 280975071 | F38: =E38*D38 -> 280975071 | G38: =공종별내역서!H938 -> 0 | H38: =G38*D38 -> 0 | I38: =공종별내역서!J938 -> 1517265 | J38: =I38*D38 -> 1517265 | K38: =E38+G38+I38 -> 282492336 | L38: =F38+H38+J38 -> 282492336 | N38: 010401 | P38: 0104 | R38: 3
A39: 010402 관급자재[관급자] | D39: 1 | E39: =공종별내역서!F964 -> 175681680 | F39: =E39*D39 -> 175681680 | G39: =공종별내역서!H964 -> 0 | H39: =G39*D39 -> 0 | I39: =공종별내역서!J964 -> 673079 | J39: =I39*D39 -> 673079 | K39: =E39+G39+I39 -> 176354759 | L39: =F39+H39+J39 -> 176354759 | N39: 010402 | P39: 0104 | R39: 3
A52: [ 합 계 ] | F52: =F5 -> 491423918 | H52: =H5 -> 635475641 | J52: =J5 -> 103491491 | L52: =L5 -> 1230391050

Sheet 공종별내역서
A1: 품 명 | B1: 규 격 | C1: 단위 | D1: 수량 | E1: 재 료 비 | G1: 노 무 비 | I1: 경 비 | K1: 합 계 | M1: 비 고 | N1: 품목코드 | O1: 변수 | P1: 설정 | Q1: 공종코드 | R1: 일위 | S1: 단산 | T1: 자재 | U1: 손료적용 | V1: 손료저장 | W1: 적용율 | X1: JUK1 | Y1: JUK2 | Z1: JUK3 | AA1: JUK4 | AB1: JUK5 | AC1: JUK6 | AD1: JUK7 | AE1: JUK8 | AF1: JUK9 | AG1: JUK10 | AH1: JUK11 | AI1: JUK12 | AJ1: JUK13 | AK1: JUK14 | AL1: JUK15 | AM1: JUK16 | AN1: JUK17 | AO1: JUK18 | AP1: JUK19 | AQ1: JUK20 | AR1: 자재구분 | AS1: 공종구분 | AT1: 공종레벨 | AU1: 공종+자재 | AV1: 고유번호
E2: 단 가 | F2: 금 액 | G2: 단 가 | H2: 금 액 | I2: 단 가 | J2: 금 액 | K2: 단 가 | L2: 금 액
A3: 010101 공통 가설 공사 | Q3: 010101
A4: 콘테이너형 가설사무소 설치 및 해체 | B4: 3.0*6.0m, 12개월 | C4: 개소 | D4: 1 | E4: =TRUNC(일위대가목록!E4,0) -> 0 | F4: =TRUNC(E4*D4, 0) -> 0 | G4: =TRUNC(일위대가목록!F4,0) -> 0 | H4: =TRUNC(G4*D4, 0) -> 0 | I4: =TRUNC(일위대가목록!G4,0) -> 1483066 | J4: =TRUNC(I4*D4, 0) -> 1483066 | K4: =TRUNC(E4+G4+I4, 0) -> 1483066 | L4: =TRUNC(F4+H4+J4, 0) -> 1483066 | M4: 호표 1 | N4: 5D67A30D8A60E669727759098E1435 | Q4: 010101 | R4: T | S4: F | T4: F | AU4: 0101015D67A30D8A60E669727759098E1435 | AV4: 433
A5: 콘테이너형 가설창고 설치 및 해체 | B5: 3.0*6.0m, 12개월 | C5: 개소 | D5: 1 | E5: =TRUNC(일위대가목록!E5,0) -> 0 | F5: =TRUNC(E5*D5, 0) -> 0 | G5: =TRUNC(일위대가목록!F5,0) -> 0 | H5: =TRUNC(G5*D5, 0) -> 0 | I5: =TRUNC(일위대가목록!G5,0) -> 1337498 | J5: =TRUNC(I5*D5, 0) -> 1337498 | K5: =TRUNC(E5+G5+I5, 0) -> 1337498 | L5: =TRUNC(F5+H5+J5, 0) -> 1337498 | M5: 호표 2 | N5: 5D67A30D8A60D5E97E3091D99881A5 | Q5: 010101 | R5: T | S5: F | T5: F | AU5: 0101015D67A30D8A60D5E97E3091D99881A5 | AV5: 434
A6: 콘테이너형 가설실험실 설치 및 해체 | B6: 3.0*6.0m, 12개월 | C6: 개소 | D6: 1 | E6: =TRUNC(일위대가목록!E6,0) -> 0 | F6: =TRUNC(E6*D6, 0) -> 0 | G6: =TRUNC(일위대가목록!F6,0) -> 0 | H6: =TRUNC(G6*D6, 0) -> 0 | I6: =TRUNC(일위대가목록!G6,0) -> 1337498 | J6: =TRUNC(I6*D6, 0) -> 1337498 | K6: =TRUNC(E6+G6+I6, 0) -> 1337498 | L6: =TRUNC(F6+H6+J6, 0) -> 1337498 | M6: 호표 3 | N6: 5D67A30D8A60D5E97E3091D99881F5 | Q6: 010101 | R6: T | S6: F | T6: F | AU6: 0101015D67A30D8A60D5E97E3091D99881F5 | AV6: 435
A7: 가설방음벽설치/(RPP) | B7: H=3.0, 12개월 | C7: M | D7: 122 | E7: =TRUNC(일위대가목록!E7,0) -> 0 | F7: =TRUNC(E7*D7, 0) -> 0 | G7: =TRUNC(일위대가목록!F7,0) -> 0 | H7: =TRUNC(G7*D7, 0) -> 0 | I7: =TRUNC(일위대가목록!G7,0) -> 124029 | J7: =TRUNC(I7*D7, 0) -> 15131538 | K7: =TRUNC(E7+G7+I7, 0) -> 124029 | L7: =TRUNC(F7+H7+J7, 0) -> 15131538 | M7: 호표 4 | N7: 5D67A30E84A236D1756C80E96F8845 | Q7: 010101 | R7: T | S7: F | T7: F | AU7: 0101015D67A30E84A236D1756C80E96F8845 | AV7: 623
A8: 가설방음문설치/(RPP) | B8: W=10.0*H=3.0, 12개월 | C8: EA | D8: 1 | E8: =TRUNC(일위대가목록!E8,0) -> 0 | F8: =TRUNC(E8*D8, 0) -> 0 | G8: =TRUNC(일위대가목록!F8,0) -> 0 | H8: =TRUNC(G8*D8, 0) -> 0 | I8: =TRUNC(일위대가목록!G8,0) -> 1363865 | J8: =TRUNC(I8*D8, 0) -> 1363865 | K8: =TRUNC(E8+G8+I8, 0) -> 1363865 | L8: =TRUNC(F8+H8+J8, 0) -> 1363865 | M8: 호표 5 | N8: 5D67A30E84A236D1756C80E91768D5 | Q8: 010101 | R8: T | S8: F | T8: F | AU8: 0101015D67A30E84A236D1756C80E91768D5 | AV8: 624
Q9: 010101
Q10: 010101
Q11: 010101
Q12: 010101
Q13: 010101
Q14: 010101
Q15: 010101
Q16: 010101
Q17: 010101
Q18: 010101
Q19: 010101
Q20: 010101
... Q27: 010101
A28: [ 합 계 ] | F28: =SUMIF(Q4:Q27,"010101",F4:F27) -> 0 | H28: =SUMIF(Q4:Q27,"010101",H4:H27) -> 0 | J28: =SUMIF(Q4:Q27,"010101",J4:J27) -> 20653465 | L28: =SUMIF(Q4:Q27,"010101",L4:L27) -> 20653465 | N28: TOTAL
A29: 010102 가 설 공 사 | Q29: 010102
A30: 수평 규준틀 | B30: 평 | C30: 개소 | D30: 10 | E30: =TRUNC(일위대가목록!E9,0) -> 7394 | F30: =TRUNC(E30*D30, 0) -> 73940 | G30: =TRUNC(일위대가목록!F9,0) -> 92625 | H30: =TRUNC(G30*D30, 0) -> 926250 | I30: =TRUNC(일위대가목록!G9,0) -> 0 | J30: =TRUNC(I30*D30, 0) -> 0 | K30: =TRUNC(E30+G30+I30, 0) -> 100019 | L30: =TRUNC(F30+H30+J30, 0) -> 1000190 | M30: 호표 6 | N30: 5D67A30E8487698D7FC1AD69C0A0A5 | Q30: 010102 | R30: T | S30: F | T30: F | AU30: 0101025D67A30E8487698D7FC1AD69C0A0A5 | AV30: 13
A31: 수평 규준틀 | B31: 귀 | C31: 개소 | D31: 10 | E31: =TRUNC(일위대가목록!E10,0) -> 11620 | F31: =TRUNC(E31*D31, 0) -> 116200 | G31: =TRUNC(일위대가목록!F10,0) -> 159780 | H31: =TRUNC(G31*D31, 0) -> 1597800 | I31: =TRUNC(일위대가목록!G10,0) -> 0 | J31: =TRUNC(I31*D31, 0) -> 0 | K31: =TRUNC(E31+G31+I31, 0) -> 171400 | L31: =TRUNC(F31+H31+J31, 0) -> 1714000 | M31: 호표 7 | N31: 5D67A30E8487698D7FC1AE7937C605 | Q31: 010102 | R31: T | S31: F | T31: F | AU31: 0101025D67A30E8487698D7FC1AE7937C605 | AV31: 14
A32: 강관 조립말비계(이동식)설치 및 해체 | B32: 높이 2m, 3개월 | C32: 대 | D32: 6 | E32: =TRUNC(일위대가목록!E11,0) -> 39919 | F32: =TRUNC(E32*D32, 0) -> 239514 | G32: =TRUNC(일위대가목록!F11,0) -> 93630 | H32: =TRUNC(G32*D32, 0) -> 561780 | I32: =TRUNC(일위대가목록!G11,0) -> 0 | J32: =TRUNC(I32*D32, 0) -> 0 | K32: =TRUNC(E32+G32+I32, 0) -> 133549 | L32: =TRUNC(F32+H32+J32, 0) -> 801294 | M32: 호표 8 | N32: 5D67A30E8487699E71B5651960B165 | Q32: 010102 | R32: T | S32: F | T32: F | AU32: 0101025D67A30E8487699E71B5651960B165 | AV32: 10
A33: 시스템동바리 설치 및 해체(설치간격 0.6m~1.2m 이하) | B33: 10m이하, 3개월 | C33: 10공M3 | D33: 15.479 | E33: =TRUNC(일위대가목록!E12,0) -> 24974 | F33: =TRUNC(E33*D33, 0) -> 386572 | G33: =TRUNC(일위대가목록!F12,0) -> 198509 | H33: =TRUNC(G33*D33, 0) -> 3072720 | I33: =TRUNC(일위대가목록!G12,0) -> 7139 | J33: =TRUNC(I33*D33, 0) -> 110504 | K33: =TRUNC(E33+G33+I33, 0) -> 230622 | L33: =TRUNC(F33+H33+J33, 0) -> 3569796 | M33: 호표 9 | N33: 5D67A30E84875F15736AC6294AAEC5 | Q33: 010102 | R33: T | S33: F | T33: F | AU33: 0101025D67A30E84875F15736AC6294AAEC5 | AV33: 16
A34: 강관동바리 설치 및 해체 | B34: 3.5m 초과 ~ 4.2m 이하, 3개월 | C34: M2 | D34: 76 | E34: =TRUNC(일위대가목록!E13,0) -> 2225 | F34: =TRUNC(E34*D34, 0) -> 169100 | G34: =TRUNC(일위대가목록!F13,0) -> 18067 | H34: =TRUNC(G34*D34, 0) -> 1373092 | I34: =TRUNC(일위대가목록!G13,0) -> 0 | J34: =TRUNC(I34*D34, 0) -> 0 | K34: =TRUNC(E34+G34+I34, 0) -> 20292 | L34: =TRUNC(F34+H34+J34, 0) -> 1542192 | M34: 호표 10 | N34: 5D67A30E84875F047C78E3C985FDA5 | Q34: 010102 | R34: T | S34: F | T34: F | AU34: 0101025D67A30E84875F047C78E3C985FDA5 | AV34: 15
A35: 시스템비계 설치 및 해체 | B35: 9개월,10m 이하,발판포함(외부용) | C35: M2 | D35: 1389 | E35: =TRUNC(일위대가목록!E14,0) -> 4681 | F35: =TRUNC(E35*D35, 0) -> 6501909 | G35: =TRUNC(일위대가목록!F14,0) -> 12875 | H35: =TRUNC(G35*D35, 0) -> 17883375 | I35: =TRUNC(일위대가목록!G14,0) -> 0 | J35: =TRUNC(I35*D35, 0) -> 0 | K35: =TRUNC(E35+G35+I35, 0) -> 17556 | L35: =TRUNC(F35+H35+J35, 0) -> 24385284 | M35: 호표 11 | N35: 5D67A30E8487699E737D6F99FDD6C5 | Q35: 010102 | R35: T | S35: F | T35: F | AU35: 0101025D67A30E8487699E737D6F99FDD6C5 | AV35: 11
A36: 시스템비계 설치 및 해체 | B36: 9개월,10m 초과~20m 이하,발판포함(외부용) | C36: M2 | D36: 344 | E36: =TRUNC(일위대가목록!E15,0) -> 4681 | F36: =TRUNC(E36*D36, 0) -> 1610264 | G36: =TRUNC(일위대가목록!F15,0) -> 15669 | H36: =TRUNC(G36*D36, 0) -> 5390136 | I36: =TRUNC(일위대가목록!G15,0) -> 0 | J36: =TRUNC(I36*D36, 0) -> 0 | K36: =TRUNC(E36+G36+I36, 0) -> 20350 | L36: =TRUNC(F36+H36+J36, 0) -> 7000400 | M36: 호표 12 | N36: 5D67A30E8487699E737D6F99FDE725 | Q36: 010102 | R36: T | S36: F | T36: F | AU36: 0101025D67A30E8487699E737D6F99FDE725 | AV36: 12
A37: 건축물 현장정리 | B37: 철근콘크리트조, 철골·철근콘크리트조 | C37: M2 | D37: 649 | E37: =TRUNC(일위대가목록!E16,0) -> 0 | F37: =TRUNC(E37*D37, 0) -> 0 | G37: =TRUNC(일위대가목록!F16,0) -> 22074 | H37: =TRUNC(G37*D37, 0) -> 14326026 | I37: =TRUNC(일위대가목록!G16,0) -> 0 | J37: =TRUNC(I37*D37, 0) -> 0 | K37: =TRUNC(E37+G37+I37, 0) -> 22074 | L37: =TRUNC(F37+H37+J37, 0) -> 14326026 | M37: 호표 13 | N37: 5D67A30B8F6E33F27A0DA909B21E95 | Q37: 010102 | R37: T | S37: F | T37: F | AU37: 0101025D67A30B8F6E33F27A0DA909B21E95 | AV37: 17
A38: 구조부 먹매김 | B38: 일반 | C38: M2 | D38: 649 | E38: =TRUNC(일위대가목록!E17,0) -> 0 | F38: =TRUNC(E38*D38, 0) -> 0 | G38: =TRUNC(일위대가목록!F17,0) -> 1389 | H38: =TRUNC(G38*D38, 0) -> 901461 | I38: =TRUNC(일위대가목록!G17,0) -> 0 | J38: =TRUNC(I38*D38, 0) -> 0 | K38: =TRUNC(E38+G38+I38, 0) -> 1389 | L38: =TRUNC(F38+H38+J38, 0) -> 901461 | M38: 호표 14 | N38: 5D67A30B8F5DF836746C46D9926C25 | Q38: 010102 | R38: T | S38: F | T38: F | AU38: 0101025D67A30B8F5DF836746C46D9926C25 | AV38: 18
A39: 거푸집 먹매김 | B39: 일반 | C39: M2 | D39: 649 | E39: =TRUNC(일위대가목록!E18,0) -> 0 | F39: =TRUNC(E39*D39, 0) -> 0 | G39: =TRUNC(일위대가목록!F18,0) -> 3334 | H39: =TRUNC(G39*D39, 0) -> 2163766 | I39: =TRUNC(일위대가목록!G18,0) -> 0 | J39: =TRUNC(I39*D39, 0) -> 0 | K39: =TRUNC(E39+G39+I39, 0) -> 3334 | L39: =TRUNC(F39+H39+J39, 0) -> 2163766 | M39: 호표 15 | N39: 5D67A30B8F5DF836746E74D95463D5 | Q39: 010102 | R39: T | S39: F | T39: F | AU39: 0101025D67A30B8F5DF836746E74D95463D5 | AV39: 19
A40: 건축물보양 | B40: 보양지 붙이기 | C40: M2 | D40: 25 | E40: =TRUNC(일위대가목록!E19,0) -> 1052 | F40: =TRUNC(E40*D40, 0) -> 26300 | G40: =TRUNC(일위대가목록!F19,0) -> 1698 | H40: =TRUNC(G40*D40, 0) -> 42450 | I40: =TRUNC(일위대가목록!G19,0) -> 0 | J40: =TRUNC(I40*D40, 0) -> 0 | K40: =TRUNC(E40+G40+I40, 0) -> 2750 | L40: =TRUNC(F40+H40+J40, 0) -> 68750 | M40: 호표 16 | N40: 5D67A30B8F5DF8097191C5D9FA5165 | Q40: 010102 | R40: T | S40: F | T40: F | AU40: 0101025D67A30B8F5DF8097191C5D9FA5165 | AV40: 20
A41: 건축물보양 - 콘크리트 | B41: 살수 | C41: M2 | D41: 1220 | E41: =TRUNC(일위대가목록!E20,0) -> 0 | F41: =TRUNC(E41*D41, 0) -> 0 | G41: =TRUNC(일위대가목록!F20,0) -> 679 | H41: =TRUNC(G41*D41, 0) -> 828380 | I41: =TRUNC(일위대가목록!G20,0) -> 0 | J41: =TRUNC(I41*D41, 0) -> 0 | K41: =TRUNC(E41+G41+I41, 0) -> 679 | L41: =TRUNC(F41+H41+J41, 0) -> 828380 | M41: 호표 17 | N41: 5D67A30B8F5DF809708BF979B27C75 | Q41: 010102 | R41: T | S41: F | T41: F | AU41: 0101025D67A30B8F5DF809708BF979B27C75 | AV41: 21
A42: 준공청소 | C42: M2 | D42: 649 | E42: =TRUNC(일위대가목록!E21,0) -> 0 | F42: =TRUNC(E42*D42, 0) -> 0 | G42: =TRUNC(일위대가목록!F21,0) -> 3396 | H42: =TRUNC(G42*D42, 0) -> 2204004 | I42: =TRUNC(일위대가목록!G21,0) -> 0 | J42: =TRUNC(I42*D42, 0) -> 0 | K42: =TRUNC(E42+G42+I42, 0) -> 3396 | L42: =TRUNC(F42+H42+J42, 0) -> 2204004 | M42: 호표 18 | N42: 5D67A30B8F310A977BC965B9B7B765 | Q42: 010102 | R42: T | S42: F | T42: F | AU42: 0101025D67A30B8F310A977BC965B9B7B765 | AV42: 22
Q43: 010102
Q44: 010102
Q45: 010102
Q46: 010102
...

Sheet 일위대가목록
B1: 일 위 대 가 목 록
B2: [ 대화면도시재생사업청학당조성공사기본및실시설 ]
A3: 코 드 | B3: 품 명 | C3: 규 격 | D3: 단위 | E3: 재 료 비 | F3: 노 무 비 | G3: 경 비 | H3: 합 계 | I3: 번 호 | J3: 비 고 | K3: 노임계수 | L3: 할증 | M3: 품셈개요 | N3: 장비일위
A4: 5D67A30D8A60E669727759098E1435 | B4: 콘테이너형 가설사무소 설치 및 해체 | C4: 3.0*6.0m, 12개월 | D4: 개소 | E4: =일위대가!F8 -> 0 | F4: =일위대가!H8 -> 0 | G4: =일위대가!J8 -> 1483066 | H4: =E4+F4+G4 -> 1483066 | I4: 호표 1
A5: 5D67A30D8A60D5E97E3091D99881A5 | B5: 콘테이너형 가설창고 설치 및 해체 | C5: 3.0*6.0m, 12개월 | D5: 개소 | E5: =일위대가!F14 -> 0 | F5: =일위대가!H14 -> 0 | G5: =일위대가!J14 -> 1337498 | H5: =E5+F5+G5 -> 1337498 | I5: 호표 2
A6: 5D67A30D8A60D5E97E3091D99881F5 | B6: 콘테이너형 가설실험실 설치 및 해체 | C6: 3.0*6.0m, 12개월 | D6: 개소 | E6: =일위대가!F20 -> 0 | F6: =일위대가!H20 -> 0 | G6: =일위대가!J20 -> 1337498 | H6: =E6+F6+G6 -> 1337498 | I6: 호표 3
A7: 5D67A30E84A236D1756C80E96F8845 | B7: 가설방음벽설치/(RPP) | C7: H=3.0, 12개월 | D7: M | E7: =일위대가!F33 -> 0 | F7: =일위대가!H33 -> 0 | G7: =일위대가!J33 -> 124029 | H7: =E7+F7+G7 -> 124029 | I7: 호표 4
A8: 5D67A30E84A236D1756C80E91768D5 | B8: 가설방음문설치/(RPP) | C8: W=10.0*H=3.0, 12개월 | D8: EA | E8: =일위대가!F40 -> 0 | F8: =일위대가!H40 -> 0 | G8: =일위대가!J40 -> 1363865 | H8: =E8+F8+G8 -> 1363865 | I8: 호표 5
A9: 5D67A30E8487698D7FC1AD69C0A0A5 | B9: 수평 규준틀 | C9: 평 | D9: 개소 | E9: =일위대가!F46 -> 7394 | F9: =일위대가!H46 -> 92625 | G9: =일위대가!J46 -> 0 | H9: =E9+F9+G9 -> 100019 | I9: 호표 6
A10: 5D67A30E8487698D7FC1AE7937C605 | B10: 수평 규준틀 | C10: 귀 | D10: 개소 | E10: =일위대가!F52 -> 11620 | F10: =일위대가!H52 -> 159780 | G10: =일위대가!J52 -> 0 | H10: =E10+F10+G10 -> 171400 | I10: 호표 7
A11: 5D67A30E8487699E71B5651960B165 | B11: 강관 조립말비계(이동식)설치 및 해체 | C11: 높이 2m, 3개월 | D11: 대 | E11: =일위대가!F65 -> 39919 | F11: =일위대가!H65 -> 93630 | G11: =일위대가!J65 -> 0 | H11: =E11+F11+G11 -> 133549 | I11: 호표 8
A12: 5D67A30E84875F15736AC6294AAEC5 | B12: 시스템동바리 설치 및 해체(설치간격 0.6m~1.2m 이하) | C12: 10m이하, 3개월 | D12: 10공M3 | E12: =일위대가!F78 -> 24974 | F12: =일위대가!H78 -> 198509 | G12: =일위대가!J78 -> 7139 | H12: =E12+F12+G12 -> 230622 | I12: 호표 9
A13: 5D67A30E84875F047C78E3C985FDA5 | B13: 강관동바리 설치 및 해체 | C13: 3.5m 초과 ~ 4.2m 이하, 3개월 | D13: M2 | E13: =일위대가!F85 -> 2225 | F13: =일위대가!H85 -> 18067 | G13: =일위대가!J85 -> 0 | H13: =E13+F13+G13 -> 20292 | I13: 호표 10
A14: 5D67A30E8487699E737D6F99FDD6C5 | B14: 시스템비계 설치 및 해체 | C14: 9개월,10m 이하,발판포함(외부용) | D14: M2 | E14: =일위대가!F90 -> 4681 | F14: =일위대가!H90 -> 12875 | G14: =일위대가!J90 -> 0 | H14: =E14+F14+G14 -> 17556 | I14: 호표 11
A15: 5D67A30E8487699E737D6F99FDE725 | B15: 시스템비계 설치 및 해체 | C15: 9개월,10m 초과~20m 이하,발판포함(외부용) | D15: M2 | E15: =일위대가!F95 -> 4681 | F15: =일위대가!H95 -> 15669 | G15: =일위대가!J95 -> 0 | H15: =E15+F15+G15 -> 20350 | I15: 호표 12
A16: 5D67A30B8F6E33F27A0DA909B21E95 | B16: 건축물 현장정리 | C16: 철근콘크리트조, 철골·철근콘크리트조 | D16: M2 | E16: =일위대가!F99 -> 0 | F16: =일위대가!H99 -> 22074 | G16: =일위대가!J99 -> 0 | H16: =E16+F16+G16 -> 22074 | I16: 호표 13
A17: 5D67A30B8F5DF836746C46D9926C25 | B17: 구조부 먹매김 | C17: 일반 | D17: M2 | E17: =일위대가!F103 -> 0 | F17: =일위대가!H103 -> 1389 | G17: =일위대가!J103 -> 0 | H17: =E17+F17+G17 -> 1389 | I17: 호표 14
A18: 5D67A30B8F5DF836746E74D95463D5 | B18: 거푸집 먹매김 | C18: 일반 | D18: M2 | E18: =일위대가!F107 -> 0 | F18: =일위대가!H107 -> 3334 | G18: =일위대가!J107 -> 0 | H18: =E18+F18+G18 -> 3334 | I18: 호표 15
A19: 5D67A30B8F5DF8097191C5D9FA5165 | B19: 건축물보양 | C19: 보양지 붙이기 | D19: M2 | E19: =일위대가!F113 -> 1052 | F19: =일위대가!H113 -> 1698 | G19: =일위대가!J113 -> 0 | H19: =E19+F19+G19 -> 2750 | I19: 호표 16
A20: 5D67A30B8F5DF809708BF979B27C75 | B20: 건축물보양 - 콘크리트 | C20: 살수 | D20: M2 | E20: =일위대가!F117 -> 0 | F20: =일위대가!H117 -> 679 | G20: =일위대가!J117 -> 0 | H20: =E20+F20+G20 -> 679 | I20: 호표 17
A21: 5D67A30B8F310A977BC965B9B7B765 | B21: 준공청소 | D21: M2 | E21: =일위대가!F121 -> 0 | F21: =일위대가!H121 -> 3396 | G21: =일위대가!J121 -> 0 | H21: =E21+F21+G21 -> 3396 | I21: 호표 18
A22: 5D42A3E686A1DB757FC39889792385 | B22: 되메우기 및 다짐 | C22: 대형장비 | D22: M3 | E22: =일위대가!F131 -> 1511 | F22: =일위대가!H131 -> 7129 | G22: =일위대가!J131 -> 1539 | H22: =E22+F22+G22 -> 10179 | I22: 호표 19
A23: 5D67932C8F27974F785CD3A97CE615 | B23: 압출발포폴리스티렌 접착제 붙이기 | C23: 100mm, (특호) | D23: M2 | E23: =일위대가!F136 -> 16430 | F23: =일위대가!H136 -> 16183 | G23: =일위대가!J136 -> 0 | H23: =E23+F23+G23 -> 32613 | I23: 호표 20
A24: 5D67932C8F27974F785CD0D91A0875 | B24: 방습필름설치 | C24: 바닥, 0.03mm*2겹 | D24: M2 | E24: =일위대가!F141 -> 422 | F24: =일위대가!H141 -> 1431 | G24: =일위대가!J141 -> 0 | H24: =E24+F24+G24 -> 1853 | I24: 호표 21
A25: 5D42A3E7874C2EE77FD5DD8988E785 | B25: 기초 지정[잡석,자갈별도] | C25: 잡석지정 | D25: M3 | E25: =일위대가!F151 -> 1048 | F25: =일위대가!H151 -> 9384 | G25: =일위대가!J151 -> 1361 | H25: =E25+F25+G25 -> 11793 | I25: 호표 22
A26: 5D67F3978F67C568786415995E1E65 | B26: 콘크리트 펌프차 타설 | C26: slump 15cm, 매트기초 등, f2 : Type-Ⅱ, 36m | D26: M3 | E26: =일위대가!F159 -> 1450 | F26: =일위대가!H159 -> 11741 | G26: =일위대가!J159 -> 4343 | H26: =E26+F26+G26 -> 17534 | I26: 호표 23
